Workbook

Sheet 1
A1: Chandanaish Territory - Daily Sales and Target Achievement Sheet
A2: Name of Territory: | B2: Chandanaish | C2: Name of Region: | D2: Chattogram | I2: Date: | K2: 46296
A3: SL NO | B3: Name of SR / CSR | C3: Name of Route | D3: No. of Outlets | E3: Brand Wise Target | G3: Brand Wise Sales | I3: Total Sales | J3: Variance | K3: Achievement % | L3: Remarks
E4: Cigarette | F4: Bidi | G4: Cigarette | H4: Bidi
A5: =Target!A4 -> 1 | B5: =Target!B4 -> Karim | C5: =Target!C4 -> Kesua | D5: =Target!D4 | E5: =Target!G4 -> 0.05 | F5: =Target!H4 | G5: 0.05 | I5: =IF(AND(G5="",H5=""),"",SUM(G5:H5)) -> 0.05 | J5: =IF(I5="","",I5-(E5+N(F5))) -> 0 | K5: =IF(I5="","",IFERROR(I5/(E5+N(F5)),0)) -> 1 | L5: =IF(I5="","",IF(K5>=1.01,"Top Performer",IF(K5>=1,"Achieved",IF(K5>=0.98,"Near Target","Needs Pacing")))) -> Achieved
A6: =Target!A5 -> 2 | C6: =Target!C5 -> Moulvi Bazar | D6: =Target!D5 | E6: =Target!G5 -> 0.03 | F6: =Target!H5 | I6: =IF(AND(G6="",H6=""),"",SUM(G6:H6)) | J6: =IF(I6="","",I6-(E6+N(F6))) | K6: =IF(I6="","",IFERROR(I6/(E6+N(F6)),0)) | L6: =IF(I6="","",IF(K6>=1.01,"Top Performer",IF(K6>=1,"Achieved",IF(K6>=0.98,"Near Target","Needs Pacing"))))
A7: =Target!A6 -> 3 | B7: =Target!B6 -> Jabed | C7: =Target!C6 -> Char Barama | D7: =Target!D6 | E7: =Target!G6 -> 0.05 | F7: =Target!H6 | I7: =IF(AND(G7="",H7=""),"",SUM(G7:H7)) | J7: =IF(I7="","",I7-(E7+N(F7))) | K7: =IF(I7="","",IFERROR(I7/(E7+N(F7)),0)) | L7: =IF(I7="","",IF(K7>=1.01,"Top Performer",IF(K7>=1,"Achieved",IF(K7>=0.98,"Near Target","Needs Pacing"))))
A8: =Target!A7 -> 4 | C8: =Target!C7 -> Pukur Par | D8: =Target!D7 | E8: =Target!G7 -> 0.03 | F8: =Target!H7 | G8: 0.02 | I8: =IF(AND(G8="",H8=""),"",SUM(G8:H8)) -> 0.02 | J8: =IF(I8="","",I8-(E8+N(F8))) -> -0.01 | K8: =IF(I8="","",IFERROR(I8/(E8+N(F8)),0)) -> 0.66666667 | L8: =IF(I8="","",IF(K8>=1.01,"Top Performer",IF(K8>=1,"Achieved",IF(K8>=0.98,"Near Target","Needs Pacing")))) -> Needs Pacing
A9: =Target!A8 -> 5 | B9: =Target!B8 -> Anowar | C9: =Target!C8 -> Dhamair Hat | D9: =Target!D8 | E9: =Target!G8 -> 0.07 | F9: =Target!H8 | I9: =IF(AND(G9="",H9=""),"",SUM(G9:H9)) | J9: =IF(I9="","",I9-(E9+N(F9))) | K9: =IF(I9="","",IFERROR(I9/(E9+N(F9)),0)) | L9: =IF(I9="","",IF(K9>=1.01,"Top Performer",IF(K9>=1,"Achieved",IF(K9>=0.98,"Near Target","Needs Pacing"))))
A10: =Target!A9 -> 6 | C10: =Target!C9 -> Chomuda para | D10: =Target!D9 | E10: =Target!G9 -> 0.03 | F10: =Target!H9 | G10: 0.05 | I10: =IF(AND(G10="",H10=""),"",SUM(G10:H10)) -> 0.05 | J10: =IF(I10="","",I10-(E10+N(F10))) -> 0.02 | K10: =IF(I10="","",IFERROR(I10/(E10+N(F10)),0)) -> 1.6666667 | L10: =IF(I10="","",IF(K10>=1.01,"Top Performer",IF(K10>=1,"Achieved",IF(K10>=0.98,"Near Target","Needs Pacing")))) -> Top Performer
A11: =Target!A10 -> 7 | B11: =Target!B10 -> Tahasin | C11: =Target!C10 -> Harala | D11: =Target!D10 | E11: =Target!G10 -> 0.05 | F11: =Target!H10 | I11: =IF(AND(G11="",H11=""),"",SUM(G11:H11)) | J11: =IF(I11="","",I11-(E11+N(F11))) | K11: =IF(I11="","",IFERROR(I11/(E11+N(F11)),0)) | L11: =IF(I11="","",IF(K11>=1.01,"Top Performer",IF(K11>=1,"Achieved",IF(K11>=0.98,"Near Target","Needs Pacing"))))
A12: =Target!A11 -> 8 | C12: =Target!C11 -> Nazir Hat | D12: =Target!D11 | E12: =Target!G11 -> 0.03 | F12: =Target!H11 | G12: 0.05 | I12: =IF(AND(G12="",H12=""),"",SUM(G12:H12)) -> 0.05 | J12: =IF(I12="","",I12-(E12+N(F12))) -> 0.02 | K12: =IF(I12="","",IFERROR(I12/(E12+N(F12)),0)) -> 1.6666667 | L12: =IF(I12="","",IF(K12>=1.01,"Top Performer",IF(K12>=1,"Achieved",IF(K12>=0.98,"Near Target","Needs Pacing")))) -> Top Performer
A13: =Target!A12 -> 9 | B13: =Target!B12 -> Amir | C13: =Target!C12 -> khan Hat | D13: =Target!D12 | E13: =Target!G12 -> 0.08 | F13: =Target!H12 | I13: =IF(AND(G13="",H13=""),"",SUM(G13:H13)) | J13: =IF(I13="","",I13-(E13+N(F13))) | K13: =IF(I13="","",IFERROR(I13/(E13+N(F13)),0)) | L13: =IF(I13="","",IF(K13>=1.01,"Top Performer",IF(K13>=1,"Achieved",IF(K13>=0.98,"Near Target","Needs Pacing"))))
A14: =Target!A13 -> 10 | C14: =Target!C13 -> Saidabad | D14: =Target!D13 | E14: =Target!G13 -> 0.05 | F14: =Target!H13 | G14: 0.05 | I14: =IF(AND(G14="",H14=""),"",SUM(G14:H14)) -> 0.05 | J14: =IF(I14="","",I14-(E14+N(F14))) -> 0 | K14: =IF(I14="","",IFERROR(I14/(E14+N(F14)),0)) -> 1 | L14: =IF(I14="","",IF(K14>=1.01,"Top Performer",IF(K14>=1,"Achieved",IF(K14>=0.98,"Near Target","Needs Pacing")))) -> Achieved
A15: =Target!A14 -> 11 | B15: =Target!B14 -> Piplu | C15: =Target!C14 -> Hasimpur | D15: =Target!D14 | E15: =Target!G14 -> 0.05 | F15: =Target!H14 | G15: 0.08 | I15: =IF(AND(G15="",H15=""),"",SUM(G15:H15)) -> 0.08 | J15: =IF(I15="","",I15-(E15+N(F15))) -> 0.03 | K15: =IF(I15="","",IFERROR(I15/(E15+N(F15)),0)) -> 1.6 | L15: =IF(I15="","",IF(K15>=1.01,"Top Performer",IF(K15>=1,"Achieved",IF(K15>=0.98,"Near Target","Needs Pacing")))) -> Top Performer
A16: =Target!A15 -> 12 | C16: =Target!C15 -> Chandanaish | D16: =Target!D15 | E16: =Target!G15 -> 0.07 | F16: =Target!H15 | I16: =IF(AND(G16="",H16=""),"",SUM(G16:H16)) | J16: =IF(I16="","",I16-(E16+N(F16))) | K16: =IF(I16="","",IFERROR(I16/(E16+N(F16)),0)) | L16: =IF(I16="","",IF(K16>=1.01,"Top Performer",IF(K16>=1,"Achieved",IF(K16>=0.98,"Near Target","Needs Pacing"))))
A17: Territory Total | D17: =IF(COUNT(D5:D16)=0,"",SUM(D5:D16)) | E17: =SUM(E5:E16) -> 0.59 | F17: =IF(COUNT(F5:F16)=0,"",SUM(F5:F16)) | G17: =IF(COUNT(G5:G16)=0,"",SUM(G5:G16)) -> 0.3 | H17: =IF(COUNT(H5:H16)=0,"",SUM(H5:H16)) | I17: =IF(COUNT(I5:I16)=0,"",SUM(I5:I16)) -> 0.3 | J17: =IF(I17="","",I17-(E17+N(F17))) -> -0.29 | K17: =IF(I17="","",IFERROR(I17/(E17+N(F17)),0)) -> 0.50847458 | L17: =IF(I17="","",IF(K17>=1,"Achieved","Shortfall")) -> Shortfall

Sheet 2
A1: Chandanaish Territory - Daily Sales and Target Achievement Sheet
A2: Name of Territory: | B2: Chandanaish | C2: Name of Region: | D2: Chattogram | I2: Date: | K2: 46297
A3: SL NO | B3: Name of SR / CSR | C3: Name of Route | D3: No. of Outlets | E3: Brand Wise Target | G3: Brand Wise Sales | I3: Total Sales | J3: Variance | K3: Achievement % | L3: Remarks
E4: Cigarette | F4: Bidi | G4: Cigarette | H4: Bidi
A5: =Target!A4 -> 1 | B5: =Target!B4 -> Karim | C5: =Target!C4 -> Kesua | D5: =Target!D4 | E5: 0 | F5: 0 | G5: 0 | H5: 0 | I5: 0 | J5: 0 | K5: 0 | L5: Friday Off
A6: =Target!A5 -> 2 | C6: =Target!C5 -> Moulvi Bazar | D6: =Target!D5 | E6: 0 | F6: 0 | G6: 0 | H6: 0 | I6: 0 | J6: 0 | K6: 0 | L6: Friday Off
A7: =Target!A6 -> 3 | B7: =Target!B6 -> Jabed | C7: =Target!C6 -> Char Barama | D7: =Target!D6 | E7: 0 | F7: 0 | G7: 0 | H7: 0 | I7: 0 | J7: 0 | K7: 0 | L7: Friday Off
A8: =Target!A7 -> 4 | C8: =Target!C7 -> Pukur Par | D8: =Target!D7 | E8: 0 | F8: 0 | G8: 0 | H8: 0 | I8: 0 | J8: 0 | K8: 0 | L8: Friday Off
A9: =Target!A8 -> 5 | B9: =Target!B8 -> Anowar | C9: =Target!C8 -> Dhamair Hat | D9: =Target!D8 | E9: 0 | F9: 0 | G9: 0 | H9: 0 | I9: 0 | J9: 0 | K9: 0 | L9: Friday Off
A10: =Target!A9 -> 6 | C10: =Target!C9 -> Chomuda para | D10: =Target!D9 | E10: 0 | F10: 0 | G10: 0 | H10: 0 | I10: 0 | J10: 0 | K10: 0 | L10: Friday Off
A11: =Target!A10 -> 7 | B11: =Target!B10 -> Tahasin | C11: =Target!C10 -> Harala | D11: =Target!D10 | E11: 0 | F11: 0 | G11: 0 | H11: 0 | I11: 0 | J11: 0 | K11: 0 | L11: Friday Off
A12: =Target!A11 -> 8 | C12: =Target!C11 -> Nazir Hat | D12: =Target!D11 | E12: 0 | F12: 0 | G12: 0 | H12: 0 | I12: 0 | J12: 0 | K12: 0 | L12: Friday Off
A13: =Target!A12 -> 9 | B13: =Target!B12 -> Amir | C13: =Target!C12 -> khan Hat | D13: =Target!D12 | E13: 0 | F13: 0 | G13: 0 | H13: 0 | I13: 0 | J13: 0 | K13: 0 | L13: Friday Off
A14: =Target!A13 -> 10 | C14: =Target!C13 -> Saidabad | D14: =Target!D13 | E14: 0 | F14: 0 | G14: 0 | H14: 0 | I14: 0 | J14: 0 | K14: 0 | L14: Friday Off
A15: =Target!A14 -> 11 | B15: =Target!B14 -> Piplu | C15: =Target!C14 -> Hasimpur | D15: =Target!D14 | E15: 0 | F15: 0 | G15: 0 | H15: 0 | I15: 0 | J15: 0 | K15: 0 | L15: Friday Off
A16: =Target!A15 -> 12 | C16: =Target!C15 -> Chandanaish | D16: =Target!D15 | E16: 0 | F16: 0 | G16: 0 | H16: 0 | I16: 0 | J16: 0 | K16: 0 | L16: Friday Off
A17: Territory Total | D17: 0 | E17: 0 | F17: 0 | G17: 0 | H17: 0 | I17: 0 | J17: 0 | K17: 0 | L17: Friday Off

Sheet 3
A1: Chandanaish Territory - Daily Sales and Target Achievement Sheet
A2: Name of Territory: | B2: Chandanaish | C2: Name of Region: | D2: Chattogram | I2: Date: | K2: 46298
A3: SL NO | B3: Name of SR / CSR | C3: Name of Route | D3: No. of Outlets | E3: Brand Wise Target | G3: Brand Wise Sales | I3: Total Sales | J3: Variance | K3: Achievement % | L3: Remarks
E4: Cigarette | F4: Bidi | G4: Cigarette | H4: Bidi
A5: =Target!A4 -> 1 | B5: =Target!B4 -> Karim | C5: =Target!C4 -> Kesua | D5: =Target!D4 | E5: =Target!G4 -> 0.05 | F5: =Target!H4 | I5: =IF(AND(G5="",H5=""),"",SUM(G5:H5)) | J5: =IF(I5="","",I5-(E5+N(F5))) | K5: =IF(I5="","",IFERROR(I5/(E5+N(F5)),0)) | L5: =IF(I5="","",IF(K5>=1.01,"Top Performer",IF(K5>=1,"Achieved",IF(K5>=0.98,"Near Target","Needs Pacing"))))
A6: =Target!A5 -> 2 | C6: =Target!C5 -> Moulvi Bazar | D6: =Target!D5 | E6: =Target!G5 -> 0.03 | F6: =Target!H5 | G6: 0.04 | I6: =IF(AND(G6="",H6=""),"",SUM(G6:H6)) -> 0.04 | J6: =IF(I6="","",I6-(E6+N(F6))) -> 0.01 | K6: =IF(I6="","",IFERROR(I6/(E6+N(F6)),0)) -> 1.3333333 | L6: =IF(I6="","",IF(K6>=1.01,"Top Performer",IF(K6>=1,"Achieved",IF(K6>=0.98,"Near Target","Needs Pacing")))) -> Top Performer
A7: =Target!A6 -> 3 | B7: =Target!B6 -> Jabed | C7: =Target!C6 -> Char Barama | D7: =Target!D6 | E7: =Target!G6 -> 0.05 | F7: =Target!H6 | G7: 0.04 | I7: =IF(AND(G7="",H7=""),"",SUM(G7:H7)) -> 0.04 | J7: =IF(I7="","",I7-(E7+N(F7))) -> -0.01 | K7: =IF(I7="","",IFERROR(I7/(E7+N(F7)),0)) -> 0.8 | L7: =IF(I7="","",IF(K7>=1.01,"Top Performer",IF(K7>=1,"Achieved",IF(K7>=0.98,"Near Target","Needs Pacing")))) -> Needs Pacing
A8: =Target!A7 -> 4 | C8: =Target!C7 -> Pukur Par | D8: =Target!D7 | E8: =Target!G7 -> 0.03 | F8: =Target!H7 | I8: =IF(AND(G8="",H8=""),"",SUM(G8:H8)) | J8: =IF(I8="","",I8-(E8+N(F8))) | K8: =IF(I8="","",IFERROR(I8/(E8+N(F8)),0)) | L8: =IF(I8="","",IF(K8>=1.01,"Top Performer",IF(K8>=1,"Achieved",IF(K8>=0.98,"Near Target","Needs Pacing"))))
A9: =Target!A8 -> 5 | B9: =Target!B8 -> Anowar | C9: =Target!C8 -> Dhamair Hat | D9: =Target!D8 | E9: =Target!G8 -> 0.07 | F9: =Target!H8 | G9: 0.05 | I9: =IF(AND(G9="",H9=""),"",SUM(G9:H9)) -> 0.05 | J9: =IF(I9="","",I9-(E9+N(F9))) -> -0.02 | K9: =IF(I9="","",IFERROR(I9/(E9+N(F9)),0)) -> 0.71428571 | L9: =IF(I9="","",IF(K9>=1.01,"Top Performer",IF(K9>=1,"Achieved",IF(K9>=0.98,"Near Target","Needs Pacing")))) -> Needs Pacing
A10: =Target!A9 -> 6 | C10: =Target!C9 -> Chomuda para | D10: =Target!D9 | E10: =Target!G9 -> 0.03 | F10: =Target!H9 | I10: =IF(AND(G10="",H10=""),"",SUM(G10:H10)) | J10: =IF(I10="","",I10-(E10+N(F10))) | K10: =IF(I10="","",IFERROR(I10/(E10+N(F10)),0)) | L10: =IF(I10="","",IF(K10>=1.01,"Top Performer",IF(K10>=1,"Achieved",IF(K10>=0.98,"Near Target","Needs Pacing"))))
A11: =Target!A10 -> 7 | B11: =Target!B10 -> Tahasin | C11: =Target!C10 -> Harala | D11: =Target!D10 | E11: =Target!G10 -> 0.05 | F11: =Target!H10 | G11: 0.04 | I11: =IF(AND(G11="",H11=""),"",SUM(G11:H11)) -> 0.04 | J11: =IF(I11="","",I11-(E11+N(F11))) -> -0.01 | K11: =IF(I11="","",IFERROR(I11/(E11+N(F11)),0)) -> 0.8 | L11: =IF(I11="","",IF(K11>=1.01,"Top Performer",IF(K11>=1,"Achieved",IF(K11>=0.98,"Near Target","Needs Pacing")))) -> Needs Pacing
A12: =Target!A11 -> 8 | C12: =Target!C11 -> Nazir Hat | D12: =Target!D11 | E12: =Target!G11 -> 0.03 | F12: =Target!H11 | I12: =IF(AND(G12="",H12=""),"",SUM(G12:H12)) | J12: =IF(I12="","",I12-(E12+N(F12))) | K12: =IF(I12="","",IFERROR(I12/(E12+N(F12)),0)) | L12: =IF(I12="","",IF(K12>=1.01,"Top Performer",IF(K12>=1,"Achieved",IF(K12>=0.98,"Near Target","Needs Pacing"))))
A13: =Target!A12 -> 9 | B13: =Target!B12 -> Amir | C13: =Target!C12 -> khan Hat | D13: =Target!D12 | E13: =Target!G12 -> 0.08 | F13: =Target!H12 | G13: 0.07 | I13: =IF(AND(G13="",H13=""),"",SUM(G13:H13)) -> 0.07 | J13: =IF(I13="","",I13-(E13+N(F13))) -> -0.01 | K13: =IF(I13="","",IFERROR(I13/(E13+N(F13)),0)) -> 0.875 | L13: =IF(I13="","",IF(K13>=1.01,"Top Performer",IF(K13>=1,"Achieved",IF(K13>=0.98,"Near Target","Needs Pacing")))) -> Needs Pacing
A14: =Target!A13 -> 10 | C14: =Target!C13 -> Saidabad | D14: =Target!D13 | E14: =Target!G13 -> 0.05 | F14: =Target!H13 | I14: =IF(AND(G14="",H14=""),"",SUM(G14:H14)) | J14: =IF(I14="","",I14-(E14+N(F14))) | K14: =IF(I14="","",IFERROR(I14/(E14+N(F14)),0)) | L14: =IF(I14="","",IF(K14>=1.01,"Top Performer",IF(K14>=1,"Achieved",IF(K14>=0.98,"Near Target","Needs Pacing"))))
A15: =Target!A14 -> 11 | B15: =Target!B14 -> Piplu | C15: =Target!C14 -> Hasimpur | D15: =Target!D14 | E15: =Target!G14 -> 0.05 | F15: =Target!H14 | I15: =IF(AND(G15="",H15=""),"",SUM(G15:H15)) | J15: =IF(I15="","",I15-(E15+N(F15))) | K15: =IF(I15="","",IFERROR(I15/(E15+N(F15)),0)) | L15: =IF(I15="","",IF(K15>=1.01,"Top Performer",IF(K15>=1,"Achieved",IF(K15>=0.98,"Near Target","Needs Pacing"))))
A16: =Target!A15 -> 12 | C16: =Target!C15 -> Chandanaish | D16: =Target!D15 | E16: =Target!G15 -> 0.07 | F16: =Target!H15 | G16: 0.06 | I16: =IF(AND(G16="",H16=""),"",SUM(G16:H16)) -> 0.06 | J16: =IF(I16="","",I16-(E16+N(F16))) -> -0.01 | K16: =IF(I16="","",IFERROR(I16/(E16+N(F16)),0)) -> 0.85714286 | L16: =IF(I16="","",IF(K16>=1.01,"Top Performer",IF(K16>=1,"Achieved",IF(K16>=0.98,"Near Target","Needs Pacing")))) -> Needs Pacing
A17: Territory Total | D17: =IF(COUNT(D5:D16)=0,"",SUM(D5:D16)) | E17: =SUM(E5:E16) -> 0.59 | F17: =IF(COUNT(F5:F16)=0,"",SUM(F5:F16)) | G17: =IF(COUNT(G5:G16)=0,"",SUM(G5:G16)) -> 0.3 | H17: =IF(COUNT(H5:H16)=0,"",SUM(H5:H16)) | I17: =IF(COUNT(I5:I16)=0,"",SUM(I5:I16)) -> 0.3 | J17: =IF(I17="","",I17-(E17+N(F17))) -> -0.29 | K17: =IF(I17="","",IFERROR(I17/(E17+N(F17)),0)) -> 0.50847458 | L17: =IF(I17="","",IF(K17>=1,"Achieved","Shortfall")) -> Shortfall

Sheet 4
A1: Chandanaish Territory - Daily Sales and Target Achievement Sheet
A2: Name of Territory: | B2: Chandanaish | C2: Name of Region: | D2: Chattogram | I2: Date: | K2: 46299
A3: SL NO | B3: Name of SR / CSR | C3: Name of Route | D3: No. of Outlets | E3: Brand Wise Target | G3: Brand Wise Sales | I3: Total Sales | J3: Variance | K3: Achievement % | L3: Remarks
E4: Cigarette | F4: Bidi | G4: Cigarette | H4: Bidi
A5: =Target!A4 -> 1 | B5: =Target!B4 -> Karim | C5: =Target!C4 -> Kesua | D5: =Target!D4 | E5: =Target!G4 -> 0.05 | F5: =Target!H4 | G5: 0.04 | I5: =IF(AND(G5="",H5=""),"",SUM(G5:H5)) -> 0.04 | J5: =IF(I5="","",I5-(E5+N(F5))) -> -0.01 | K5: =IF(I5="","",IFERROR(I5/(E5+N(F5)),0)) -> 0.8 | L5: =IF(I5="","",IF(K5>=1.01,"Top Performer",IF(K5>=1,"Achieved",IF(K5>=0.98,"Near Target","Needs Pacing")))) -> Needs Pacing
A6: =Target!A5 -> 2 | C6: =Target!C5 -> Moulvi Bazar | D6: =Target!D5 | E6: =Target!G5 -> 0.03 | F6: =Target!H5 | I6: =IF(AND(G6="",H6=""),"",SUM(G6:H6)) | J6: =IF(I6="","",I6-(E6+N(F6))) | K6: =IF(I6="","",IFERROR(I6/(E6+N(F6)),0)) | L6: =IF(I6="","",IF(K6>=1.01,"Top Performer",IF(K6>=1,"Achieved",IF(K6>=0.98,"Near Target","Needs Pacing"))))
A7: =Target!A6 -> 3 | B7: =Target!B6 -> Jabed | C7: =Target!C6 -> Char Barama | D7: =Target!D6 | E7: =Target!G6 -> 0.05 | F7: =Target!H6 | I7: =IF(AND(G7="",H7=""),"",SUM(G7:H7)) | J7: =IF(I7="","",I7-(E7+N(F7))) | K7: =IF(I7="","",IFERROR(I7/(E7+N(F7)),0)) | L7: =IF(I7="","",IF(K7>=1.01,"Top Performer",IF(K7>=1,"Achieved",IF(K7>=0.98,"Near Target","Needs Pacing"))))
A8: =Target!A7 -> 4 | C8: =Target!C7 -> Pukur Par | D8: =Target!D7 | E8: =Target!G7 -> 0.03 | F8: =Target!H7 | G8: 0.04 | I8: =IF(AND(G8="",H8=""),"",SUM(G8:H8)) -> 0.04 | J8: =IF(I8="","",I8-(E8+N(F8))) -> 0.01 | K8: =IF(I8="","",IFERROR(I8/(E8+N(F8)),0)) -> 1.3333333 | L8: =IF(I8="","",IF(K8>=1.01,"Top Performer",IF(K8>=1,"Achieved",IF(K8>=0.98,"Near Target","Needs Pacing")))) -> Top Performer
A9: =Target!A8 -> 5 | B9: =Target!B8 -> Anowar | C9: =Target!C8 -> Dhamair Hat | D9: =Target!D8 | E9: =Target!G8 -> 0.07 | F9: =Target!H8 | I9: =IF(AND(G9="",H9=""),"",SUM(G9:H9)) | J9: =IF(I9="","",I9-(E9+N(F9))) | K9: =IF(I9="","",IFERROR(I9/(E9+N(F9)),0)) | L9: =IF(I9="","",IF(K9>=1.01,"Top Performer",IF(K9>=1,"Achieved",IF(K9>=0.98,"Near Target","Needs Pacing"))))
A10: =Target!A9 -> 6 | C10: =Target!C9 -> Chomuda para | D10: =Target!D9 | E10: =Target!G9 -> 0.03 | F10: =Target!H9 | G10: 0.04 | I10: =IF(AND(G10="",H10=""),"",SUM(G10:H10)) -> 0.04 | J10: =IF(I10="","",I10-(E10+N(F10))) -> 0.01 | K10: =IF(I10="","",IFERROR(I10/(E10+N(F10)),0)) -> 1.3333333 | L10: =IF(I10="","",IF(K10>=1.01,"Top Performer",IF(K10>=1,"Achieved",IF(K10>=0.98,"Near Target","Needs Pacing")))) -> Top Performer
A11: =Target!A10 -> 7 | B11: =Target!B10 -> Tahasin | C11: =Target!C10 -> Harala | D11: =Target!D10 | E11: =Target!G10 -> 0.05 | F11: =Target!H10 | I11: =IF(AND(G11="",H11=""),"",SUM(G11:H11)) | J11: =IF(I11="","",I11-(E11+N(F11))) | K11: =IF(I11="","",IFERROR(I11/(E11+N(F11)),0)) | L11: =IF(I11="","",IF(K11>=1.01,"Top Performer",IF(K11>=1,"Achieved",IF(K11>=0.98,"Near Target","Needs Pacing"))))
A12: =Target!A11 -> 8 | C12: =Target!C11 -> Nazir Hat | D12: =Target!D11 | E12: =Target!G11 -> 0.03 | F12: =Target!H11 | G12: 0.04 | I12: =IF(AND(G12="",H12=""),"",SUM(G12:H12)) -> 0.04 | J12: =IF(I12="","",I12-(E12+N(F12))) -> 0.01 | K12: =IF(I12="","",IFERROR(I12/(E12+N(F12)),0)) -> 1.3333333 | L12: =IF(I12="","",IF(K12>=1.01,"Top Performer",IF(K12>=1,"Achieved",IF(K12>=0.98,"Near Target","Needs Pacing")))) -> Top Performer
A13: =Target!A12 -> 9 | B13: =Target!B12 -> Amir | C13: =Target!C12 -> khan Hat | D13: =Target!D12 | E13: =Target!G12 -> 0.08 | F13: =Target!H12 | I13: =IF(AND(G13="",H13=""),"",SUM(G13:H13)) | J13: =IF(I13="","",I13-(E13+N(F13))) | K13: =IF(I13="","",IFERROR(I13/(E13+N(F13)),0)) | L13: =IF(I13="","",IF(K13>=1.01,"Top Performer",IF(K13>=1,"Achieved",IF(K13>=0.98,"Near Target","Needs Pacing"))))
A14: =Target!A13 -> 10 | C14: =Target!C13 -> Saidabad | D14: =Target!D13 | E14: =Target!G13 -> 0.05 | F14: =Target!H13 | G14: 0.09 | I14: =IF(AND(G14="",H14=""),"",SUM(G14:H14)) -> 0.09 | J14: =IF(I14="","",I14-(E14+N(F14))) -> 0.04 | K14: =IF(I14="","",IFERROR(I14/(E14+N(F14)),0)) -> 1.8 | L14: =IF(I14="","",IF(K14>=1.01,"Top Performer",IF(K14>=1,"Achieved",IF(K14>=0.98,"Near Target","Needs Pacing")))) -> Top Performer
A15: =Target!A14 -> 11 | B15: =Target!B14 -> Piplu | C15: =Target!C14 -> Hasimpur | D15: =Target!D14 | E15: =Target!G14 -> 0.05 | F15: =Target!H14 | G15: 0.08 | I15: =IF(AND(G15="",H15=""),"",SUM(G15:H15)) -> 0.08 | J15: =IF(I15="","",I15-(E15+N(F15))) -> 0.03 | K15: =IF(I15="","",IFERROR(I15/(E15+N(F15)),0)) -> 1.6 | L15: =IF(I15="","",IF(K15>=1.01,"Top Performer",IF(K15>=1,"Achieved",IF(K15>=0.98,"Near Target","Needs Pacing")))) -> Top Performer
A16: =Target!A15 -> 12 | C16: =Target!C15 -> Chandanaish | D16: =Target!D15 | E16: =Target!G15 -> 0.07 | F16: =Target!H15 | I16: =IF(AND(G16="",H16=""),"",SUM(G16:H16)) | J16: =IF(I16="","",I16-(E16+N(F16))) | K16: =IF(I16="","",IFERROR(I16/(E16+N(F16)),0)) | L16: =IF(I16="","",IF(K16>=1.01,"Top Performer",IF(K16>=1,"Achieved",IF(K16>=0.98,"Near Target","Needs Pacing"))))
A17: Territory Total | D17: =IF(COUNT(D5:D16)=0,"",SUM(D5:D16)) | E17: =SUM(E5:E16) -> 0.59 | F17: =IF(COUNT(F5:F16)=0,"",SUM(F5:F16)) | G17: =IF(COUNT(G5:G16)=0,"",SUM(G5:G16)) -> 0.33 | H17: =IF(COUNT(H5:H16)=0,"",SUM(H5:H16)) | I17: =IF(COUNT(I5:I16)=0,"",SUM(I5:I16)) -> 0.33 | J17: =IF(I17="","",I17-(E17+N(F17))) -> -0.26 | K17: =IF(I17="","",IFERROR(I17/(E17+N(F17)),0)) -> 0.55932203 | L17: =IF(I17="","",IF(K17>=1,"Achieved","Shortfall")) -> Shortfall

Sheet 5
A1: Chandanaish Territory - Daily Sales and Target Achievement Sheet
A2: Name of Territory: | B2: Chandanaish | C2: Name of Region: | D2: Chattogram | I2: Date: | K2: 46300
A3: SL NO | B3: Name of SR / CSR | C3: Name of Route | D3: No. of Outlets | E3: Brand Wise Target | G3: Brand Wise Sales | I3: Total Sales | J3: Variance | K3: Achievement % | L3: Remarks
E4: Cigarette | F4: Bidi | G4: Cigarette | H4: Bidi
A5: =Target!A4 -> 1 | B5: =Target!B4 -> Karim | C5: =Target!C4 -> Kesua | D5: =Target!D4 | E5: =Target!G4 -> 0.05 | F5: =Target!H4 | I5: =IF(AND(G5="",H5=""),"",SUM(G5:H5)) | J5: =IF(I5="","",I5-(E5+N(F5))) | K5: =IF(I5="","",IFERROR(I5/(E5+N(F5)),0)) | L5: =IF(I5="","",IF(K5>=1.01,"Top Performer",IF(K5>=1,"Achieved",IF(K5>=0.98,"Near Target","Needs Pacing"))))
A6: =Target!A5 -> 2 | C6: =Target!C5 -> Moulvi Bazar | D6: =Target!D5 | E6: =Target!G5 -> 0.03 | F6: =Target!H5 | G6: 0.04 | I6: =IF(AND(G6="",H6=""),"",SUM(G6:H6)) -> 0.04 | J6: =IF(I6="","",I6-(E6+N(F6))) -> 0.01 | K6: =IF(I6="","",IFERROR(I6/(E6+N(F6)),0)) -> 1.3333333 | L6: =IF(I6="","",IF(K6>=1.01,"Top Performer",IF(K6>=1,"Achieved",IF(K6>=0.98,"Near Target","Needs Pacing")))) -> Top Performer
A7: =Target!A6 -> 3 | B7: =Target!B6 -> Jabed | C7: =Target!C6 -> Char Barama | D7: =Target!D6 | E7: =Target!G6 -> 0.05 | F7: =Target!H6 | G7: 0.06 | I7: =IF(AND(G7="",H7=""),"",SUM(G7:H7)) -> 0.06 | J7: =IF(I7="","",I7-(E7+N(F7))) -> 0.01 | K7: =IF(I7="","",IFERROR(I7/(E7+N(F7)),0)) -> 1.2 | L7: =IF(I7="","",IF(K7>=1.01,"Top Performer",IF(K7>=1,"Achieved",IF(K7>=0.98,"Near Target","Needs Pacing")))) -> Top Performer
A8: =Target!A7 -> 4 | C8: =Target!C7 -> Pukur Par | D8: =Target!D7 | E8: =Target!G7 -> 0.03 | F8: =Target!H7 | I8: =IF(AND(G8="",H8=""),"",SUM(G8:H8)) | J8: =IF(I8="","",I8-(E8+N(F8))) | K8: =IF(I8="","",IFERROR(I8/(E8+N(F8)),0)) | L8: =IF(I8="","",IF(K8>=1.01,"Top Performer",IF(K8>=1,"Achieved",IF(K8>=0.98,"Near Target","Needs Pacing"))))
A9: =Target!A8 -> 5 | B9: =Target!B8 -> Anowar | C9: =Target!C8 -> Dhamair Hat | D9: =Target!D8 | E9: =Target!G8 -> 0.07 | F9: =Target!H8 | G9: 0.08 | I9: =IF(AND(G9="",H9=""),"",SUM(G9:H9)) -> 0.08 | J9: =IF(I9="","",I9-(E9+N(F9))) -> 0.01 | K9: =IF(I9="","",IFERROR(I9/(E9+N(F9)),0)) -> 1.1428571 | L9: =IF(I9="","",IF(K9>=1.01,"Top Performer",IF(K9>=1,"Achieved",IF(K9>=0.98,"Near Target","Needs Pacing")))) -> Top Performer
A10: =Target!A9 -> 6 | C10: =Target!C9 -> Chomuda para | D10: =Target!D9 | E10: =Target!G9 -> 0.03 | F10: =Target!H9 | I10: =IF(AND(G10="",H10=""),"",SUM(G10:H10)) | J10: =IF(I10="","",I10-(E10+N(F10))) | K10: =IF(I10="","",IFERROR(I10/(E10+N(F10)),0)) | L10: =IF(I10="","",IF(K10>=1.01,"Top Performer",IF(K10>=1,"Achieved",IF(K10>=0.98,"Near Target","Needs Pacing"))))
A11: =Target!A10 -> 7 | B11: =Target!B10 -> Tahasin | C11: =Target!C10 -> Harala | D11: =Target!D10 | E11: =Target!G10 -> 0.05 | F11: =Target!H10 | G11: 0.04 | I11: =IF(AND(G11="",H11=""),"",SUM(G11:H11)) -> 0.04 | J11: =IF(I11="","",I11-(E11+N(F11))) -> -0.01 | K11: =IF(I11="","",IFERROR(I11/(E11+N(F11)),0)) -> 0.8 | L11: =IF(I11="","",IF(K11>=1.01,"Top Performer",IF(K11>=1,"Achieved",IF(K11>=0.98,"Near Target","Needs Pacing")))) -> Needs Pacing
A12: =Target!A11 -> 8 | C12: =Target!C11 -> Nazir Hat | D12: =Target!D11 | E12: =Target!G11 -> 0.03 | F12: =Target!H11 | I12: =IF(AND(G12="",H12=""),"",SUM(G12:H12)) | J12: =IF(I12="","",I12-(E12+N(F12))) | K12: =IF(I12="","",IFERROR(I12/(E12+N(F12)),0)) | L12: =IF(I12="","",IF(K12>=1.01,"Top Performer",IF(K12>=1,"Achieved",IF(K12>=0.98,"Near Target","Needs Pacing"))))
A13: =Target!A12 -> 9 | B13: =Target!B12 -> Amir | C13: =Target!C12 -> khan Hat | D13: =Target!D12 | E13: =Target!G12 -> 0.08 | F13: =Target!H12 | G13: 0.09 | I13: =IF(AND(G13="",H13=""),"",SUM(G13:H13)) -> 0.09 | J13: =IF(I13="","",I13-(E13+N(F13))) -> 0.01 | K13: =IF(I13="","",IFERROR(I13/(E13+N(F13)),0)) -> 1.125 | L13: =IF(I13="","",IF(K13>=1.01,"Top Performer",IF(K13>=1,"Achieved",IF(K13>=0.98,"Near Target","Needs Pacing")))) -> Top Performer
A14: =Target!A13 -> 10 | C14: =Target!C13 -> Saidabad | D14: =Target!D13 | E14: =Target!G13 -> 0.05 | F14: =Target!H13 | I14: =IF(AND(G14="",H14=""),"",SUM(G14:H14)) | J14: =IF(I14="","",I14-(E14+N(F14))) | K14: =IF(I14="","",IFERROR(I14/(E14+N(F14)),0)) | L14: =IF(I14="","",IF(K14>=1.01,"Top Performer",IF(K14>=1,"Achieved",IF(K14>=0.98,"Near Target","Needs Pacing"))))
A15: =Target!A14 -> 11 | B15: =Target!B14 -> Piplu | C15: =Target!C14 -> Hasimpur | D15: =Target!D14 | E15: =Target!G14 -> 0.05 | F15: =Target!H14 | I15: =IF(AND(G15="",H15=""),"",SUM(G15:H15)) | J15: =IF(I15="","",I15-(E15+N(F15))) | K15: =IF(I15="","",IFERROR(I15/(E15+N(F15)),0)) | L15: =IF(I15="","",IF(K15>=1.01,"Top Performer",IF(K15>=1,"Achieved",IF(K15>=0.98,"Near Target","Needs Pacing"))))
A16: =Target!A15 -> 12 | C16: =Target!C15 -> Chandanaish | D16: =Target!D15 | E16: =Target!G15 -> 0.07 | F16: =Target!H15 | G16: 0.08 | I16: =IF(AND(G16="",H16=""),"",SUM(G16:H16)) -> 0.08 | J16: =IF(I16="","",I16-(E16+N(F16))) -> 0.01 | K16: =IF(I16="","",IFERROR(I16/(E16+N(F16)),0)) -> 1.1428571 | L16: =IF(I16="","",IF(K16>=1.01,"Top Performer",IF(K16>=1,"Achieved",IF(K16>=0.98,"Near Target","Needs Pacing")))) -> Top Performer
A17: Territory Total | D17: =IF(COUNT(D5:D16)=0,"",SUM(D5:D16)) | E17: =SUM(E5:E16) -> 0.59 | F17: =IF(COUNT(F5:F16)=0,"",SUM(F5:F16)) | G17: =IF(COUNT(G5:G16)=0,"",SUM(G5:G16)) -> 0.39 | H17: =IF(COUNT(H5:H16)=0,"",SUM(H5:H16)) | I17: =IF(COUNT(I5:I16)=0,"",SUM(I5:I16)) -> 0.39 | J17: =IF(I17="","",I17-(E17+N(F17))) -> -0.2 | K17: =IF(I17="","",IFERROR(I17/(E17+N(F17)),0)) -> 0.66101695 | L17: =IF(I17="","",IF(K17>=1,"Achieved","Shortfall")) -> Shortfall

Sheet 6
A1: Chandanaish Territory - Daily Sales and Target Achievement Sheet
A2: Name of Territory: | B2: Chandanaish | C2: Name of Region: | D2: Chattogram | I2: Date: | K2: 46301
A3: SL NO | B3: Name of SR / CSR | C3: Name of Route | D3: No. of Outlets | E3: Brand Wise Target | G3: Brand Wise Sales | I3: Total Sales | J3: Variance | K3: Achievement % | L3: Remarks
E4: Cigarette | F4: Bidi | G4: Cigarette | H4: Bidi
A5: =Target!A4 -> 1 | B5: =Target!B4 -> Karim | C5: =Target!C4 -> Kesua | D5: =Target!D4 | E5: =Target!G4 -> 0.05 | F5: =Target!H4 | G5: 0.03 | I5: =IF(AND(G5="",H5=""),"",SUM(G5:H5)) -> 0.03 | J5: =IF(I5="","",I5-(E5+N(F5))) -> -0.02 | K5: =IF(I5="","",IFERROR(I5/(E5+N(F5)),0)) -> 0.6 | L5: =IF(I5="","",IF(K5>=1.01,"Top Performer",IF(K5>=1,"Achieved",IF(K5>=0.98,"Near Target","Needs Pacing")))) -> Needs Pacing
A6: =Target!A5 -> 2 | C6: =Target!C5 -> Moulvi Bazar | D6: =Target!D5 | E6: =Target!G5 -> 0.03 | F6: =Target!H5 | I6: =IF(AND(G6="",H6=""),"",SUM(G6:H6)) | J6: =IF(I6="","",I6-(E6+N(F6))) | K6: =IF(I6="","",IFERROR(I6/(E6+N(F6)),0)) | L6: =IF(I6="","",IF(K6>=1.01,"Top Performer",IF(K6>=1,"Achieved",IF(K6>=0.98,"Near Target","Needs Pacing"))))
A7: =Target!A6 -> 3 | B7: =Target!B6 -> Jabed | C7: =Target!C6 -> Char Barama | D7: =Target!D6 | E7: =Target!G6 -> 0.05 | F7: =Target!H6 | I7: =IF(AND(G7="",H7=""),"",SUM(G7:H7)) | J7: =IF(I7="","",I7-(E7+N(F7))) | K7: =IF(I7="","",IFERROR(I7/(E7+N(F7)),0)) | L7: =IF(I7="","",IF(K7>=1.01,"Top Performer",IF(K7>=1,"Achieved",IF(K7>=0.98,"Near Target","Needs Pacing"))))
A8: =Target!A7 -> 4 | C8: =Target!C7 -> Pukur Par | D8: =Target!D7 | E8: =Target!G7 -> 0.03 | F8: =Target!H7 | G8: 0.05 | I8: =IF(AND(G8="",H8=""),"",SUM(G8:H8)) -> 0.05 | J8: =IF(I8="","",I8-(E8+N(F8))) -> 0.02 | K8: =IF(I8="","",IFERROR(I8/(E8+N(F8)),0)) -> 1.6666667 | L8: =IF(I8="","",IF(K8>=1.01,"Top Performer",IF(K8>=1,"Achieved",IF(K8>=0.98,"Near Target","Needs Pacing")))) -> Top Performer
A9: =Target!A8 -> 5 | B9: =Target!B8 -> Anowar | C9: =Target!C8 -> Dhamair Hat | D9: =Target!D8 | E9: =Target!G8 -> 0.07 | F9: =Target!H8 | I9: =IF(AND(G9="",H9=""),"",SUM(G9:H9)) | J9: =IF(I9="","",I9-(E9+N(F9))) | K9: =IF(I9="","",IFERROR(I9/(E9+N(F9)),0)) | L9: =IF(I9="","",IF(K9>=1.01,"Top Performer",IF(K9>=1,"Achieved",IF(K9>=0.98,"Near Target","Needs Pacing"))))
A10: =Target!A9 -> 6 | C10: =Target!C9 -> Chomuda para | D10: =Target!D9 | E10: =Target!G9 -> 0.03 | F10: =Target!H9 | G10: 0.15 | I10: =IF(AND(G10="",H10=""),"",SUM(G10:H10)) -> 0.15 | J10: =IF(I10="","",I10-(E10+N(F10))) -> 0.12 | K10: =IF(I10="","",IFERROR(I10/(E10+N(F10)),0)) -> 5 | L10: =IF(I10="","",IF(K10>=1.01,"Top Performer",IF(K10>=1,"Achieved",IF(K10>=0.98,"Near Target","Needs Pacing")))) -> Top Performer
A11: =Target!A10 -> 7 | B11: =Target!B10 -> Tahasin | C11: =Target!C10 -> Harala | D11: =Target!D10 | E11: =Target!G10 -> 0.05 | F11: =Target!H10 | I11: =IF(AND(G11="",H11=""),"",SUM(G11:H11)) | J11: =IF(I11="","",I11-(E11+N(F11))) | K11: =IF(I11="","",IFERROR(I11/(E11+N(F11)),0)) | L11: =IF(I11="","",IF(K11>=1.01,"Top Performer",IF(K11>=1,"Achieved",IF(K11>=0.98,"Near Target","Needs Pacing"))))
A12: =Target!A11 -> 8 | C12: =Target!C11 -> Nazir Hat | D12: =Target!D11 | E12: =Target!G11 -> 0.03 | F12: =Target!H11 | G12: 0.03 | I12: =IF(AND(G12="",H12=""),"",SUM(G12:H12)) -> 0.03 | J12: =IF(I12="","",I12-(E12+N(F12))) -> 0 | K12: =IF(I12="","",IFERROR(I12/(E12+N(F12)),0)) -> 1 | L12: =IF(I12="","",IF(K12>=1.01,"Top Performer",IF(K12>=1,"Achieved",IF(K12>=0.98,"Near Target","Needs Pacing")))) -> Achieved
A13: =Target!A12 -> 9 | B13: =Target!B12 -> Amir | C13: =Target!C12 -> khan Hat | D13: =Target!D12 | E13: =Target!G12 -> 0.08 | F13: =Target!H12 | I13: =IF(AND(G13="",H13=""),"",SUM(G13:H13)) | J13: =IF(I13="","",I13-(E13+N(F13))) | K13: =IF(I13="","",IFERROR(I13/(E13+N(F13)),0)) | L13: =IF(I13="","",IF(K13>=1.01,"Top Performer",IF(K13>=1,"Achieved",IF(K13>=0.98,"Near Target","Needs Pacing"))))
A14: =Target!A13 -> 10 | C14: =Target!C13 -> Saidabad | D14: =Target!D13 | E14: =Target!G13 -> 0.05 | F14: =Target!H13 | G14: 0.08 | I14: =IF(AND(G14="",H14=""),"",SUM(G14:H14)) -> 0.08 | J14: =IF(I14="","",I14-(E14+N(F14))) -> 0.03 | K14: =IF(I14="","",IFERROR(I14/(E14+N(F14)),0)) -> 1.6 | L14: =IF(I14="","",IF(K14>=1.01,"Top Performer",IF(K14>=1,"Achieved",IF(K14>=0.98,"Near Target","Needs Pacing")))) -> Top Performer
A15: =Target!A14 -> 11 | B15: =Target!B14 -> Piplu | C15: =Target!C14 -> Hasimpur | D15: =Target!D14 | E15: =Target!G14 -> 0.05 | F15: =Target!H14 | G15: 0.06 | I15: =IF(AND(G15="",H15=""),"",SUM(G15:H15)) -> 0.06 | J15: =IF(I15="","",I15-(E15+N(F15))) -> 0.01 | K15: =IF(I15="","",IFERROR(I15/(E15+N(F15)),0)) -> 1.2 | L15: =IF(I15="","",IF(K15>=1.01,"Top Performer",IF(K15>=1,"Achieved",IF(K15>=0.98,"Near Target","Needs Pacing")))) -> Top Performer
A16: =Target!A15 -> 12 | C16: =Target!C15 -> Chandanaish | D16: =Target!D15 | E16: =Target!G15 -> 0.07 | F16: =Target!H15 | I16: =IF(AND(G16="",H16=""),"",SUM(G16:H16)) | J16: =IF(I16="","",I16-(E16+N(F16))) | K16: =IF(I16="","",IFERROR(I16/(E16+N(F16)),0)) | L16: =IF(I16="","",IF(K16>=1.01,"Top Performer",IF(K16>=1,"Achieved",IF(K16>=0.98,"Near Target","Needs Pacing"))))
A17: Territory Total | D17: =IF(COUNT(D5:D16)=0,"",SUM(D5:D16)) | E17: =SUM(E5:E16) -> 0.59 | F17: =IF(COUNT(F5:F16)=0,"",SUM(F5:F16)) | G17: =IF(COUNT(G5:G16)=0,"",SUM(G5:G16)) -> 0.4 | H17: =IF(COUNT(H5:H16)=0,"",SUM(H5:H16)) | I17: =IF(COUNT(I5:I16)=0,"",SUM(I5:I16)) -> 0.4 | J17: =IF(I17="","",I17-(E17+N(F17))) -> -0.19 | K17: =IF(I17="","",IFERROR(I17/(E17+N(F17)),0)) -> 0.6779661 | L17: =IF(I17="","",IF(K17>=1,"Achieved","Shortfall")) -> Shortfall

Sheet 7
A1: Chandanaish Territory - Daily Sales and Target Achievement Sheet
A2: Name of Territory: | B2: Chandanaish | C2: Name of Region: | D2: Chattogram | I2: Date: | K2: 46302
A3: SL NO | B3: Name of SR / CSR | C3: Name of Route | D3: No. of Outlets | E3: Brand Wise Target | G3: Brand Wise Sales | I3: Total Sales | J3: Variance | K3: Achievement % | L3: Remarks
E4: Cigarette | F4: Bidi | G4: Cigarette | H4: Bidi
A5: =Target!A4 -> 1 | B5: =Target!B4 -> Karim | C5: =Target!C4 -> Kesua | D5: =Target!D4 | E5: =Target!G4 -> 0.05 | F5: =Target!H4 | I5: =IF(AND(G5="",H5=""),"",SUM(G5:H5)) | J5: =IF(I5="","",I5-(E5+N(F5))) | K5: =IF(I5="","",IFERROR(I5/(E5+N(F5)),0)) | L5: =IF(I5="","",IF(K5>=1.01,"Top Performer",IF(K5>=1,"Achieved",IF(K5>=0.98,"Near Target","Needs Pacing"))))
A6: =Target!A5 -> 2 | C6: =Target!C5 -> Moulvi Bazar | D6: =Target!D5 | E6: =Target!G5 -> 0.03 | F6: =Target!H5 | G6: 0.04 | I6: =IF(AND(G6="",H6=""),"",SUM(G6:H6)) -> 0.04 | J6: =IF(I6="","",I6-(E6+N(F6))) -> 0.01 | K6: =IF(I6="","",IFERROR(I6/(E6+N(F6)),0)) -> 1.3333333 | L6: =IF(I6="","",IF(K6>=1.01,"Top Performer",IF(K6>=1,"Achieved",IF(K6>=0.98,"Near Target","Needs Pacing")))) -> Top Performer
A7: =Target!A6 -> 3 | B7: =Target!B6 -> Jabed | C7: =Target!C6 -> Char Barama | D7: =Target!D6 | E7: =Target!G6 -> 0.05 | F7: =Target!H6 | G7: 0.04 | I7: =IF(AND(G7="",H7=""),"",SUM(G7:H7)) -> 0.04 | J7: =IF(I7="","",I7-(E7+N(F7))) -> -0.01 | K7: =IF(I7="","",IFERROR(I7/(E7+N(F7)),0)) -> 0.8 | L7: =IF(I7="","",IF(K7>=1.01,"Top Performer",IF(K7>=1,"Achieved",IF(K7>=0.98,"Near Target","Needs Pacing")))) -> Needs Pacing
A8: =Target!A7 -> 4 | C8: =Target!C7 -> Pukur Par | D8: =Target!D7 | E8: =Target!G7 -> 0.03 | F8: =Target!H7 | I8: =IF(AND(G8="",H8=""),"",SUM(G8:H8)) | J8: =IF(I8="","",I8-(E8+N(F8))) | K8: =IF(I8="","",IFERROR(I8/(E8+N(F8)),0)) | L8: =IF(I8="","",IF(K8>=1.01,"Top Performer",IF(K8>=1,"Achieved",IF(K8>=0.98,"Near Target","Needs Pacing"))))
A9: =Target!A8 -> 5 | B9: =Target!B8 -> Anowar | C9: =Target!C8 -> Dhamair Hat | D9: =Target!D8 | E9: =Target!G8 -> 0.07 | F9: =Target!H8 | G9: 0.07 | I9: =IF(AND(G9="",H9=""),"",SUM(G9:H9)) -> 0.07 | J9: =IF(I9="","",I9-(E9+N(F9))) -> 0 | K9: =IF(I9="","",IFERROR(I9/(E9+N(F9)),0)) -> 1 | L9: =IF(I9="","",IF(K9>=1.01,"Top Performer",IF(K9>=1,"Achieved",IF(K9>=0.98,"Near Target","Needs Pacing")))) -> Achieved
A10: =Target!A9 -> 6 | C10: =Target!C9 -> Chomuda para | D10: =Target!D9 | E10: =Target!G9 -> 0.03 | F10: =Target!H9 | I10: =IF(AND(G10="",H10=""),"",SUM(G10:H10)) | J10: =IF(I10="","",I10-(E10+N(F10))) | K10: =IF(I10="","",IFERROR(I10/(E10+N(F10)),0)) | L10: =IF(I10="","",IF(K10>=1.01,"Top Performer",IF(K10>=1,"Achieved",IF(K10>=0.98,"Near Target","Needs Pacing"))))
A11: =Target!A10 -> 7 | B11: =Target!B10 -> Tahasin | C11: =Target!C10 -> Harala | D11: =Target!D10 | E11: =Target!G10 -> 0.05 | F11: =Target!H10 | G11: 0.04 | I11: =IF(AND(G11="",H11=""),"",SUM(G11:H11)) -> 0.04 | J11: =IF(I11="","",I11-(E11+N(F11))) -> -0.01 | K11: =IF(I11="","",IFERROR(I11/(E11+N(F11)),0)) -> 0.8 | L11: =IF(I11="","",IF(K11>=1.01,"Top Performer",IF(K11>=1,"Achieved",IF(K11>=0.98,"Near Target","Needs Pacing")))) -> Needs Pacing
A12: =Target!A11 -> 8 | C12: =Target!C11 -> Nazir Hat | D12: =Target!D11 | E12: =Target!G11 -> 0.03 | F12: =Target!H11 | I12: =IF(AND(G12="",H12=""),"",SUM(G12:H12)) | J12: =IF(I12="","",I12-(E12+N(F12))) | K12: =IF(I12="","",IFERROR(I12/(E12+N(F12)),0)) | L12: =IF(I12="","",IF(K12>=1.01,"Top Performer",IF(K12>=1,"Achieved",IF(K12>=0.98,"Near Target","Needs Pacing"))))
A13: =Target!A12 -> 9 | B13: =Target!B12 -> Amir | C13: =Target!C12 -> khan Hat | D13: =Target!D12 | E13: =Target!G12 -> 0.08 | F13: =Target!H12 | G13: 0.11 | I13: =IF(AND(G13="",H13=""),"",SUM(G13:H13)) -> 0.11 | J13: =IF(I13="","",I13-(E13+N(F13))) -> 0.03 | K13: =IF(I13="","",IFERROR(I13/(E13+N(F13)),0)) -> 1.375 | L13: =IF(I13="","",IF(K13>=1.01,"Top Performer",IF(K13>=1,"Achieved",IF(K13>=0.98,"Near Target","Needs Pacing")))) -> Top Performer
A14: =Target!A13 -> 10 | C14: =Target!C13 -> Saidabad | D14: =Target!D13 | E14: =Target!G13 -> 0.05 | F14: =Target!H13 | I14: =IF(AND(G14="",H14=""),"",SUM(G14:H14)) | J14: =IF(I14="","",I14-(E14+N(F14))) | K14: =IF(I14="","",IFERROR(I14/(E14+N(F14)),0)) | L14: =IF(I14="","",IF(K14>=1.01,"Top Performer",IF(K14>=1,"Achieved",IF(K14>=0.98,"Near Target","Needs Pacing"))))
A15: =Target!A14 -> 11 | B15: =Target!B14 -> Piplu | C15: =Target!C14 -> Hasimpur | D15: =Target!D14 | E15: =Target!G14 -> 0.05 | F15: =Target!H14 | I15: =IF(AND(G15="",H15=""),"",SUM(G15:H15)) | J15: =IF(I15="","",I15-(E15+N(F15))) | K15: =IF(I15="","",IFERROR(I15/(E15+N(F15)),0)) | L15: =IF(I15="","",IF(K15>=1.01,"Top Performer",IF(K15>=1,"Achieved",IF(K15>=0.98,"Near Target","Needs Pacing"))))
A16: =Target!A15 -> 12 | C16: =Target!C15 -> Chandanaish | D16: =Target!D15 | E16: =Target!G15 -> 0.07 | F16: =Target!H15 | G16: 0.08 | I16: =IF(AND(G16="",H16=""),"",SUM(G16:H16)) -> 0.08 | J16: =IF(I16="","",I16-(E16+N(F16))) -> 0.01 | K16: =IF(I16="","",IFERROR(I16/(E16+N(F16)),0)) -> 1.1428571 | L16: =IF(I16="","",IF(K16>=1.01,"Top Performer",IF(K16>=1,"Achieved",IF(K16>=0.98,"Near Target","Needs Pacing")))) -> Top Performer
A17: Territory Total | D17: =IF(COUNT(D5:D16)=0,"",SUM(D5:D16)) | E17: =SUM(E5:E16) -> 0.59 | F17: =IF(COUNT(F5:F16)=0,"",SUM(F5:F16)) | G17: =IF(COUNT(G5:G16)=0,"",SUM(G5:G16)) -> 0.38 | H17: =IF(COUNT(H5:H16)=0,"",SUM(H5:H16)) | I17: =IF(COUNT(I5:I16)=0,"",SUM(I5:I16)) -> 0.38 | J17: =IF(I17="","",I17-(E17+N(F17))) -> -0.21 | K17: =IF(I17="","",IFERROR(I17/(E17+N(F17)),0)) -> 0.6440678 | L17: =IF(I17="","",IF(K17>=1,"Achieved","Shortfall")) -> Shortfall

Sheet 8
A1: Chandanaish Territory - Daily Sales and Target Achievement Sheet
A2: Name of Territory: | B2: Chandanaish | C2: Name of Region: | D2: Chattogram | I2: Date: | K2: 46303
A3: SL NO | B3: Name of SR / CSR | C3: Name of Route | D3: No. of Outlets | E3: Brand Wise Target | G3: Brand Wise Sales | I3: Total Sales | J3: Variance | K3: Achievement % | L3: Remarks
E4: Cigarette | F4: Bidi | G4: Cigarette | H4: Bidi
A5: =Target!A4 -> 1 | B5: =Target!B4 -> Karim | C5: =Target!C4 -> Kesua | D5: =Target!D4 | E5: =Target!G4 -> 0.05 | F5: =Target!H4 | G5: 0.05 | I5: =IF(AND(G5="",H5=""),"",SUM(G5:H5)) -> 0.05 | J5: =IF(I5="","",I5-(E5+N(F5))) -> 0 | K5: =IF(I5="","",IFERROR(I5/(E5+N(F5)),0)) -> 1 | L5: =IF(I5="","",IF(K5>=1.01,"Top Performer",IF(K5>=1,"Achieved",IF(K5>=0.98,"Near Target","Needs Pacing")))) -> Achieved
A6: =Target!A5 -> 2 | C6: =Target!C5 -> Moulvi Bazar | D6: =Target!D5 | E6: =Target!G5 -> 0.03 | F6: =Target!H5 | I6: =IF(AND(G6="",H6=""),"",SUM(G6:H6)) | J6: =IF(I6="","",I6-(E6+N(F6))) | K6: =IF(I6="","",IFERROR(I6/(E6+N(F6)),0)) | L6: =IF(I6="","",IF(K6>=1.01,"Top Performer",IF(K6>=1,"Achieved",IF(K6>=0.98,"Near Target","Needs Pacing"))))
A7: =Target!A6 -> 3 | B7: =Target!B6 -> Jabed | C7: =Target!C6 -> Char Barama | D7: =Target!D6 | E7: =Target!G6 -> 0.05 | F7: =Target!H6 | I7: =IF(AND(G7="",H7=""),"",SUM(G7:H7)) | J7: =IF(I7="","",I7-(E7+N(F7))) | K7: =IF(I7="","",IFERROR(I7/(E7+N(F7)),0)) | L7: =IF(I7="","",IF(K7>=1.01,"Top Performer",IF(K7>=1,"Achieved",IF(K7>=0.98,"Near Target","Needs Pacing"))))
A8: =Target!A7 -> 4 | C8: =Target!C7 -> Pukur Par | D8: =Target!D7 | E8: =Target!G7 -> 0.03 | F8: =Target!H7 | G8: 0.04 | I8: =IF(AND(G8="",H8=""),"",SUM(G8:H8)) -> 0.04 | J8: =IF(I8="","",I8-(E8+N(F8))) -> 0.01 | K8: =IF(I8="","",IFERROR(I8/(E8+N(F8)),0)) -> 1.3333333 | L8: =IF(I8="","",IF(K8>=1.01,"Top Performer",IF(K8>=1,"Achieved",IF(K8>=0.98,"Near Target","Needs Pacing")))) -> Top Performer
A9: =Target!A8 -> 5 | B9: =Target!B8 -> Anowar | C9: =Target!C8 -> Dhamair Hat | D9: =Target!D8 | E9: =Target!G8 -> 0.07 | F9: =Target!H8 | I9: =IF(AND(G9="",H9=""),"",SUM(G9:H9)) | J9: =IF(I9="","",I9-(E9+N(F9))) | K9: =IF(I9="","",IFERROR(I9/(E9+N(F9)),0)) | L9: =IF(I9="","",IF(K9>=1.01,"Top Performer",IF(K9>=1,"Achieved",IF(K9>=0.98,"Near Target","Needs Pacing"))))
A10: =Target!A9 -> 6 | C10: =Target!C9 -> Chomuda para | D10: =Target!D9 | E10: =Target!G9 -> 0.03 | F10: =Target!H9 | G10: 0.04 | I10: =IF(AND(G10="",H10=""),"",SUM(G10:H10)) -> 0.04 | J10: =IF(I10="","",I10-(E10+N(F10))) -> 0.01 | K10: =IF(I10="","",IFERROR(I10/(E10+N(F10)),0)) -> 1.3333333 | L10: =IF(I10="","",IF(K10>=1.01,"Top Performer",IF(K10>=1,"Achieved",IF(K10>=0.98,"Near Target","Needs Pacing")))) -> Top Performer
A11: =Target!A10 -> 7 | B11: =Target!B10 -> Tahasin | C11: =Target!C10 -> Harala | D11: =Target!D10 | E11: =Target!G10 -> 0.05 | F11: =Target!H10 | I11: =IF(AND(G11="",H11=""),"",SUM(G11:H11)) | J11: =IF(I11="","",I11-(E11+N(F11))) | K11: =IF(I11="","",IFERROR(I11/(E11+N(F11)),0)) | L11: =IF(I11="","",IF(K11>=1.01,"Top Performer",IF(K11>=1,"Achieved",IF(K11>=0.98,"Near Target","Needs Pacing"))))
A12: =Target!A11 -> 8 | C12: =Target!C11 -> Nazir Hat | D12: =Target!D11 | E12: =Target!G11 -> 0.03 | F12: =Target!H11 | G12: 0.07 | I12: =IF(AND(G12="",H12=""),"",SUM(G12:H12)) -> 0.07 | J12: =IF(I12="","",I12-(E12+N(F12))) -> 0.04 | K12: =IF(I12="","",IFERROR(I12/(E12+N(F12)),0)) -> 2.3333333 | L12: =IF(I12="","",IF(K12>=1.01,"Top Performer",IF(K12>=1,"Achieved",IF(K12>=0.98,"Near Target","Needs Pacing")))) -> Top Performer
A13: =Target!A12 -> 9 | B13: =Target!B12 -> Amir | C13: =Target!C12 -> khan Hat | D13: =Target!D12 | E13: =Target!G12 -> 0.08 | F13: =Target!H12 | I13: =IF(AND(G13="",H13=""),"",SUM(G13:H13)) | J13: =IF(I13="","",I13-(E13+N(F13))) | K13: =IF(I13="","",IFERROR(I13/(E13+N(F13)),0)) | L13: =IF(I13="","",IF(K13>=1.01,"Top Performer",IF(K13>=1,"Achieved",IF(K13>=0.98,"Near Target","Needs Pacing"))))
A14: =Target!A13 -> 10 | C14: =Target!C13 -> Saidabad | D14: =Target!D13 | E14: =Target!G13 -> 0.05 | F14: =Target!H13 | G14: 0.16 | I14: =IF(AND(G14="",H14=""),"",SUM(G14:H14)) -> 0.16 | J14: =IF(I14="","",I14-(E14+N(F14))) -> 0.11 | K14: =IF(I14="","",IFERROR(I14/(E14+N(F14)),0)) -> 3.2 | L14: =IF(I14="","",IF(K14>=1.01,"Top Performer",IF(K14>=1,"Achieved",IF(K14>=0.98,"Near Target","Needs Pacing")))) -> Top Performer
A15: =Target!A14 -> 11 | B15: =Target!B14 -> Piplu | C15: =Target!C14 -> Hasimpur | D15: =Target!D14 | E15: =Target!G14 -> 0.05 | F15: =Target!H14 | G15: 0.06 | I15: =IF(AND(G15="",H15=""),"",SUM(G15:H15)) -> 0.06 | J15: =IF(I15="","",I15-(E15+N(F15))) -> 0.01 | K15: =IF(I15="","",IFERROR(I15/(E15+N(F15)),0)) -> 1.2 | L15: =IF(I15="","",IF(K15>=1.01,"Top Performer",IF(K15>=1,"Achieved",IF(K15>=0.98,"Near Target","Needs Pacing")))) -> Top Performer
A16: =Target!A15 -> 12 | C16: =Target!C15 -> Chandanaish | D16: =Target!D15 | E16: =Target!G15 -> 0.07 | F16: =Target!H15 | I16: =IF(AND(G16="",H16=""),"",SUM(G16:H16)) | J16: =IF(I16="","",I16-(E16+N(F16))) | K16: =IF(I16="","",IFERROR(I16/(E16+N(F16)),0)) | L16: =IF(I16="","",IF(K16>=1.01,"Top Performer",IF(K16>=1,"Achieved",IF(K16>=0.98,"Near Target","Needs Pacing"))))
A17: Territory Total | D17: =IF(COUNT(D5:D16)=0,"",SUM(D5:D16)) | E17: =SUM(E5:E16) -> 0.59 | F17: =IF(COUNT(F5:F16)=0,"",SUM(F5:F16)) | G17: =IF(COUNT(G5:G16)=0,"",SUM(G5:G16)) -> 0.42 | H17: =IF(COUNT(H5:H16)=0,"",SUM(H5:H16)) | I17: =IF(COUNT(I5:I16)=0,"",SUM(I5:I16)) -> 0.42 | J17: =IF(I17="","",I17-(E17+N(F17))) -> -0.17 | K17: =IF(I17="","",IFERROR(I17/(E17+N(F17)),0)) -> 0.71186441 | L17: =IF(I17="","",IF(K17>=1,"Achieved","Shortfall")) -> Shortfall

Sheet 9
A1: Chandanaish Territory - Daily Sales and Target Achievement Sheet
A2: Name of Territory: | B2: Chandanaish | C2: Name of Region: | D2: Chattogram | I2: Date: | K2: 46304
A3: SL NO | B3: Name of SR / CSR | C3: Name of Route | D3: No. of Outlets | E3: Brand Wise Target | G3: Brand Wise Sales | I3: Total Sales | J3: Variance | K3: Achievement % | L3: Remarks
E4: Cigarette | F4: Bidi | G4: Cigarette | H4: Bidi
A5: =Target!A4 -> 1 | B5: =Target!B4 -> Karim | C5: =Target!C4 -> Kesua | D5: =Target!D4 | E5: 0 | F5: 0 | G5: 0 | H5: 0 | I5: 0 | J5: 0 | K5: 0 | L5: Friday Off
A6: =Target!A5 -> 2 | C6: =Target!C5 -> Moulvi Bazar | D6: =Target!D5 | E6: 0 | F6: 0 | G6: 0 | H6: 0 | I6: 0 | J6: 0 | K6: 0 | L6: Friday Off
A7: =Target!A6 -> 3 | B7: =Target!B6 -> Jabed | C7: =Target!C6 -> Char Barama | D7: =Target!D6 | E7: 0 | F7: 0 | G7: 0 | H7: 0 | I7: 0 | J7: 0 | K7: 0 | L7: Friday Off
A8: =Target!A7 -> 4 | C8: =Target!C7 -> Pukur Par | D8: =Target!D7 | E8: 0 | F8: 0 | G8: 0 | H8: 0 | I8: 0 | J8: 0 | K8: 0 | L8: Friday Off
A9: =Target!A8 -> 5 | B9: =Target!B8 -> Anowar | C9: =Target!C8 -> Dhamair Hat | D9: =Target!D8 | E9: 0 | F9: 0 | G9: 0 | H9: 0 | I9: 0 | J9: 0 | K9: 0 | L9: Friday Off
A10: =Target!A9 -> 6 | C10: =Target!C9 -> Chomuda para | D10: =Target!D9 | E10: 0 | F10: 0 | G10: 0 | H10: 0 | I10: 0 | J10: 0 | K10: 0 | L10: Friday Off
A11: =Target!A10 -> 7 | B11: =Target!B10 -> Tahasin | C11: =Target!C10 -> Harala | D11: =Target!D10 | E11: 0 | F11: 0 | G11: 0 | H11: 0 | I11: 0 | J11: 0 | K11: 0 | L11: Friday Off
A12: =Target!A11 -> 8 | C12: =Target!C11 -> Nazir Hat | D12: =Target!D11 | E12: 0 | F12: 0 | G12: 0 | H12: 0 | I12: 0 | J12: 0 | K12: 0 | L12: Friday Off
A13: =Target!A12 -> 9 | B13: =Target!B12 -> Amir | C13: =Target!C12 -> khan Hat | D13: =Target!D12 | E13: 0 | F13: 0 | G13: 0 | H13: 0 | I13: 0 | J13: 0 | K13: 0 | L13: Friday Off
A14: =Target!A13 -> 10 | C14: =Target!C13 -> Saidabad | D14: =Target!D13 | E14: 0 | F14: 0 | G14: 0 | H14: 0 | I14: 0 | J14: 0 | K14: 0 | L14: Friday Off
A15: =Target!A14 -> 11 | B15: =Target!B14 -> Piplu | C15: =Target!C14 -> Hasimpur | D15: =Target!D14 | E15: 0 | F15: 0 | G15: 0 | H15: 0 | I15: 0 | J15: 0 | K15: 0 | L15: Friday Off
A16: =Target!A15 -> 12 | C16: =Target!C15 -> Chandanaish | D16: =Target!D15 | E16: 0 | F16: 0 | G16: 0 | H16: 0 | I16: 0 | J16: 0 | K16: 0 | L16: Friday Off
A17: Territory Total | D17: 0 | E17: 0 | F17: 0 | G17: 0 | H17: 0 | I17: 0 | J17: 0 | K17: 0 | L17: Friday Off

Sheet 10
A1: Chandanaish Territory - Daily Sales and Target Achievement Sheet
A2: Name of Territory: | B2: Chandanaish | C2: Name of Region: | D2: Chattogram | I2: Date: | K2: 46305
A3: SL NO | B3: Name of SR / CSR | C3: Name of Route | D3: No. of Outlets | E3: Brand Wise Target | G3: Brand Wise Sales | I3: Total Sales | J3: Variance | K3: Achievement % | L3: Remarks
E4: Cigarette | F4: Bidi | G4: Cigarette | H4: Bidi
A5: =Target!A4 -> 1 | B5: =Target!B4 -> Karim | C5: =Target!C4 -> Kesua | D5: =Target!D4 | E5: =Target!G4 -> 0.05 | F5: =Target!H4 | I5: =IF(AND(G5="",H5=""),"",SUM(G5:H5)) | J5: =IF(I5="","",I5-(E5+N(F5))) | K5: =IF(I5="","",IFERROR(I5/(E5+N(F5)),0)) | L5: =IF(I5="","",IF(K5>=1.01,"Top Performer",IF(K5>=1,"Achieved",IF(K5>=0.98,"Near Target","Needs Pacing"))))
A6: =Target!A5 -> 2 | C6: =Target!C5 -> Moulvi Bazar | D6: =Target!D5 | E6: =Target!G5 -> 0.03 | G6: 0.05 | I6: =IF(AND(G6="",H6=""),"",SUM(G6:H6)) -> 0.05 | J6: =IF(I6="","",I6-(E6+N(F6))) -> 0.02 | K6: =IF(I6="","",IFERROR(I6/(E6+N(F6)),0)) -> 1.6666667 | L6: =IF(I6="","",IF(K6>=1.01,"Top Performer",IF(K6>=1,"Achieved",IF(K6>=0.98,"Near Target","Needs Pacing")))) -> Top Performer
A7: =Target!A6 -> 3 | B7: =Target!B6 -> Jabed | C7: =Target!C6 -> Char Barama | D7: =Target!D6 | E7: =Target!G6 -> 0.05 | G7: 0.07 | I7: =IF(AND(G7="",H7=""),"",SUM(G7:H7)) -> 0.07 | J7: =IF(I7="","",I7-(E7+N(F7))) -> 0.02 | K7: =IF(I7="","",IFERROR(I7/(E7+N(F7)),0)) -> 1.4 | L7: =IF(I7="","",IF(K7>=1.01,"Top Performer",IF(K7>=1,"Achieved",IF(K7>=0.98,"Near Target","Needs Pacing")))) -> Top Performer
A8: =Target!A7 -> 4 | C8: =Target!C7 -> Pukur Par | D8: =Target!D7 | E8: =Target!G7 -> 0.03 | F8: =Target!H7 | I8: =IF(AND(G8="",H8=""),"",SUM(G8:H8)) | J8: =IF(I8="","",I8-(E8+N(F8))) | K8: =IF(I8="","",IFERROR(I8/(E8+N(F8)),0)) | L8: =IF(I8="","",IF(K8>=1.01,"Top Performer",IF(K8>=1,"Achieved",IF(K8>=0.98,"Near Target","Needs Pacing"))))
A9: =Target!A8 -> 5 | B9: =Target!B8 -> Anowar | C9: =Target!C8 -> Dhamair Hat | D9: =Target!D8 | E9: =Target!G8 -> 0.07 | G9: 0.08 | I9: =IF(AND(G9="",H9=""),"",SUM(G9:H9)) -> 0.08 | J9: =IF(I9="","",I9-(E9+N(F9))) -> 0.01 | K9: =IF(I9="","",IFERROR(I9/(E9+N(F9)),0)) -> 1.1428571 | L9: =IF(I9="","",IF(K9>=1.01,"Top Performer",IF(K9>=1,"Achieved",IF(K9>=0.98,"Near Target","Needs Pacing")))) -> Top Performer
A10: =Target!A9 -> 6 | C10: =Target!C9 -> Chomuda para | D10: =Target!D9 | E10: =Target!G9 -> 0.03 | F10: =Target!H9 | I10: =IF(AND(G10="",H10=""),"",SUM(G10:H10)) | J10: =IF(I10="","",I10-(E10+N(F10))) | K10: =IF(I10="","",IFERROR(I10/(E10+N(F10)),0)) | L10: =IF(I10="","",IF(K10>=1.01,"Top Performer",IF(K10>=1,"Achieved",IF(K10>=0.98,"Near Target","Needs Pacing"))))
A11: =Target!A10 -> 7 | B11: =Target!B10 -> Tahasin | C11: =Target!C10 -> Harala | D11: =Target!D10 | E11: =Target!G10 -> 0.05 | G11: 0.05 | I11: =IF(AND(G11="",H11=""),"",SUM(G11:H11)) -> 0.05 | J11: =IF(I11="","",I11-(E11+N(F11))) -> 0 | K11: =IF(I11="","",IFERROR(I11/(E11+N(F11)),0)) -> 1 | L11: =IF(I11="","",IF(K11>=1.01,"Top Performer",IF(K11>=1,"Achieved",IF(K11>=0.98,"Near Target","Needs Pacing")))) -> Achieved
A12: =Target!A11 -> 8 | C12: =Target!C11 -> Nazir Hat | D12: =Target!D11 | E12: =Target!G11 -> 0.03 | F12: =Target!H11 | I12: =IF(AND(G12="",H12=""),"",SUM(G12:H12)) | J12: =IF(I12="","",I12-(E12+N(F12))) | K12: =IF(I12="","",IFERROR(I12/(E12+N(F12)),0)) | L12: =IF(I12="","",IF(K12>=1.01,"Top Performer",IF(K12>=1,"Achieved",IF(K12>=0.98,"Near Target","Needs Pacing"))))
A13: =Target!A12 -> 9 | B13: =Target!B12 -> Amir | C13: =Target!C12 -> khan Hat | D13: =Target!D12 | E13: =Target!G12 -> 0.08 | G13: 0.1 | I13: =IF(AND(G13="",H13=""),"",SUM(G13:H13)) -> 0.1 | J13: =IF(I13="","",I13-(E13+N(F13))) -> 0.02 | K13: =IF(I13="","",IFERROR(I13/(E13+N(F13)),0)) -> 1.25 | L13: =IF(I13="","",IF(K13>=1.01,"Top Performer",IF(K13>=1,"Achieved",IF(K13>=0.98,"Near Target","Needs Pacing")))) -> Top Performer
A14: =Target!A13 -> 10 | C14: =Target!C13 -> Saidabad | D14: =Target!D13 | E14: =Target!G13 -> 0.05 | F14: =Target!H13 | I14: =IF(AND(G14="",H14=""),"",SUM(G14:H14)) | J14: =IF(I14="","",I14-(E14+N(F14))) | K14: =IF(I14="","",IFERROR(I14/(E14+N(F14)),0)) | L14: =IF(I14="","",IF(K14>=1.01,"Top Performer",IF(K14>=1,"Achieved",IF(K14>=0.98,"Near Target","Needs Pacing"))))
A15: =Target!A14 -> 11 | B15: =Target!B14 -> Piplu | C15: =Target!C14 -> Hasimpur | D15: =Target!D14 | E15: =Target!G14 -> 0.05 | F15: =Target!H14 | I15: =IF(AND(G15="",H15=""),"",SUM(G15:H15)) | J15: =IF(I15="","",I15-(E15+N(F15))) | K15: =IF(I15="","",IFERROR(I15/(E15+N(F15)),0)) | L15: =IF(I15="","",IF(K15>=1.01,"Top Performer",IF(K15>=1,"Achieved",IF(K15>=0.98,"Near Target","Needs Pacing"))))
A16: =Target!A15 -> 12 | C16: =Target!C15 -> Chandanaish | D16: =Target!D15 | E16: =Target!G15 -> 0.07 | G16: 0.09 | I16: =IF(AND(G16="",H16=""),"",SUM(G16:H16)) -> 0.09 | J16: =IF(I16="","",I16-(E16+N(F16))) -> 0.02 | K16: =IF(I16="","",IFERROR(I16/(E16+N(F16)),0)) -> 1.2857143 | L16: =IF(I16="","",IF(K16>=1.01,"Top Performer",IF(K16>=1,"Achieved",IF(K16>=0.98,"Near Target","Needs Pacing")))) -> Top Performer
A17: Territory Total | D17: =IF(COUNT(D5:D16)=0,"",SUM(D5:D16)) | E17: =SUM(E5:E16) -> 0.59 | F17: =IF(COUNT(F5:F16)=0,"",SUM(F5:F16)) | G17: =IF(COUNT(G5:G16)=0,"",SUM(G5:G16)) -> 0.44 | H17: =IF(COUNT(H5:H16)=0,"",SUM(H5:H16)) | I17: =IF(COUNT(I5:I16)=0,"",SUM(I5:I16)) -> 0.44 | J17: =IF(I17="","",I17-(E17+N(F17))) -> -0.15 | K17: =IF(I17="","",IFERROR(I17/(E17+N(F17)),0)) -> 0.74576271 | L17: =IF(I17="","",IF(K17>=1,"Achieved","Shortfall")) -> Shortfall

Sheet 11
A1: Chandanaish Territory - Daily Sales and Target Achievement Sheet
A2: Name of Territory: | B2: Chandanaish | C2: Name of Region: | D2: Chattogram | I2: Date: | K2: 46306
A3: SL NO | B3: Name of SR / CSR | C3: Name of Route | D3: No. of Outlets | E3: Brand Wise Target | G3: Brand Wise Sales | I3: Total Sales | J3: Variance | K3: Achievement % | L3: Remarks
E4: Cigarette | F4: Bidi | G4: Cigarette | H4: Bidi
A5: =Target!A4 -> 1 | B5: =Target!B4 -> Karim | C5: =Target!C4 -> Kesua | D5: =Target!D4 | E5: =Target!G4 -> 0.05 | F5: =Target!H4 | G5: 0.05 | I5: =IF(AND(G5="",H5=""),"",SUM(G5:H5)) -> 0.05 | J5: =IF(I5="","",I5-(E5+N(F5))) -> 0 | K5: =IF(I5="","",IFERROR(I5/(E5+N(F5)),0)) -> 1 | L5: =IF(I5="","",IF(K5>=1.01,"Top Performer",IF(K5>=1,"Achieved",IF(K5>=0.98,"Near Target","Needs Pacing")))) -> Achieved
A6: =Target!A5 -> 2 | C6: =Target!C5 -> Moulvi Bazar | D6: =Target!D5 | E6: =Target!G5 -> 0.03 | F6: =Target!H5 | I6: =IF(AND(G6="",H6=""),"",SUM(G6:H6)) | J6: =IF(I6="","",I6-(E6+N(F6))) | K6: =IF(I6="","",IFERROR(I6/(E6+N(F6)),0)) | L6: =IF(I6="","",IF(K6>=1.01,"Top Performer",IF(K6>=1,"Achieved",IF(K6>=0.98,"Near Target","Needs Pacing"))))
A7: =Target!A6 -> 3 | B7: =Target!B6 -> Jabed | C7: =Target!C6 -> Char Barama | D7: =Target!D6 | E7: =Target!G6 -> 0.05 | F7: =Target!H6 | I7: =IF(AND(G7="",H7=""),"",SUM(G7:H7)) | J7: =IF(I7="","",I7-(E7+N(F7))) | K7: =IF(I7="","",IFERROR(I7/(E7+N(F7)),0)) | L7: =IF(I7="","",IF(K7>=1.01,"Top Performer",IF(K7>=1,"Achieved",IF(K7>=0.98,"Near Target","Needs Pacing"))))
A8: =Target!A7 -> 4 | C8: =Target!C7 -> Pukur Par | D8: =Target!D7 | E8: =Target!G7 -> 0.03 | F8: =Target!H7 | G8: 0.05 | I8: =IF(AND(G8="",H8=""),"",SUM(G8:H8)) -> 0.05 | J8: =IF(I8="","",I8-(E8+N(F8))) -> 0.02 | K8: =IF(I8="","",IFERROR(I8/(E8+N(F8)),0)) -> 1.6666667 | L8: =IF(I8="","",IF(K8>=1.01,"Top Performer",IF(K8>=1,"Achieved",IF(K8>=0.98,"Near Target","Needs Pacing")))) -> Top Performer
A9: =Target!A8 -> 5 | B9: =Target!B8 -> Anowar | C9: =Target!C8 -> Dhamair Hat | D9: =Target!D8 | E9: =Target!G8 -> 0.07 | F9: =Target!H8 | I9: =IF(AND(G9="",H9=""),"",SUM(G9:H9)) | J9: =IF(I9="","",I9-(E9+N(F9))) | K9: =IF(I9="","",IFERROR(I9/(E9+N(F9)),0)) | L9: =IF(I9="","",IF(K9>=1.01,"Top Performer",IF(K9>=1,"Achieved",IF(K9>=0.98,"Near Target","Needs Pacing"))))
A10: =Target!A9 -> 6 | C10: =Target!C9 -> Chomuda para | D10: =Target!D9 | E10: =Target!G9 -> 0.03 | F10: =Target!H9 | G10: 0.05 | I10: =IF(AND(G10="",H10=""),"",SUM(G10:H10)) -> 0.05 | J10: =IF(I10="","",I10-(E10+N(F10))) -> 0.02 | K10: =IF(I10="","",IFERROR(I10/(E10+N(F10)),0)) -> 1.6666667 | L10: =IF(I10="","",IF(K10>=1.01,"Top Performer",IF(K10>=1,"Achieved",IF(K10>=0.98,"Near Target","Needs Pacing")))) -> Top Performer
A11: =Target!A10 -> 7 | B11: =Target!B10 -> Tahasin | C11: =Target!C10 -> Harala | D11: =Target!D10 | E11: =Target!G10 -> 0.05 | F11: =Target!H10 | I11: =IF(AND(G11="",H11=""),"",SUM(G11:H11)) | J11: =IF(I11="","",I11-(E11+N(F11))) | K11: =IF(I11="","",IFERROR(I11/(E11+N(F11)),0)) | L11: =IF(I11="","",IF(K11>=1.01,"Top Performer",IF(K11>=1,"Achieved",IF(K11>=0.98,"Near Target","Needs Pacing"))))
A12: =Target!A11 -> 8 | C12: =Target!C11 -> Nazir Hat | D12: =Target!D11 | E12: =Target!G11 -> 0.03 | F12: =Target!H11 | G12: 0.05 | I12: =IF(AND(G12="",H12=""),"",SUM(G12:H12)) -> 0.05 | J12: =IF(I12="","",I12-(E12+N(F12))) -> 0.02 | K12: =IF(I12="","",IFERROR(I12/(E12+N(F12)),0)) -> 1.6666667 | L12: =IF(I12="","",IF(K12>=1.01,"Top Performer",IF(K12>=1,"Achieved",IF(K12>=0.98,"Near Target","Needs Pacing")))) -> Top Performer
A13: =Target!A12 -> 9 | B13: =Target!B12 -> Amir | C13: =Target!C12 -> khan Hat | D13: =Target!D12 | E13: =Target!G12 -> 0.08 | F13: =Target!H12 | I13: =IF(AND(G13="",H13=""),"",SUM(G13:H13)) | J13: =IF(I13="","",I13-(E13+N(F13))) | K13: =IF(I13="","",IFERROR(I13/(E13+N(F13)),0)) | L13: =IF(I13="","",IF(K13>=1.01,"Top Performer",IF(K13>=1,"Achieved",IF(K13>=0.98,"Near Target","Needs Pacing"))))
A14: =Target!A13 -> 10 | C14: =Target!C13 -> Saidabad | D14: =Target!D13 | E14: =Target!G13 -> 0.05 | F14: =Target!H13 | G14: 0.1 | I14: =IF(AND(G14="",H14=""),"",SUM(G14:H14)) -> 0.1 | J14: =IF(I14="","",I14-(E14+N(F14))) -> 0.05 | K14: =IF(I14="","",IFERROR(I14/(E14+N(F14)),0)) -> 2 | L14: =IF(I14="","",IF(K14>=1.01,"Top Performer",IF(K14>=1,"Achieved",IF(K14>=0.98,"Near Target","Needs Pacing")))) -> Top Performer
A15: =Target!A14 -> 11 | B15: =Target!B14 -> Piplu | C15: =Target!C14 -> Hasimpur | D15: =Target!D14 | E15: =Target!G14 -> 0.05 | F15: =Target!H14 | G15: 0.08 | I15: =IF(AND(G15="",H15=""),"",SUM(G15:H15)) -> 0.08 | J15: =IF(I15="","",I15-(E15+N(F15))) -> 0.03 | K15: =IF(I15="","",IFERROR(I15/(E15+N(F15)),0)) -> 1.6 | L15: =IF(I15="","",IF(K15>=1.01,"Top Performer",IF(K15>=1,"Achieved",IF(K15>=0.98,"Near Target","Needs Pacing")))) -> Top Performer
A16: =Target!A15 -> 12 | C16: =Target!C15 -> Chandanaish | D16: =Target!D15 | E16: =Target!G15 -> 0.07 | F16: =Target!H15 | I16: =IF(AND(G16="",H16=""),"",SUM(G16:H16)) | J16: =IF(I16="","",I16-(E16+N(F16))) | K16: =IF(I16="","",IFERROR(I16/(E16+N(F16)),0)) | L16: =IF(I16="","",IF(K16>=1.01,"Top Performer",IF(K16>=1,"Achieved",IF(K16>=0.98,"Near Target","Needs Pacing"))))
A17: Territory Total | D17: =IF(COUNT(D5:D16)=0,"",SUM(D5:D16)) | E17: =SUM(E5:E16) -> 0.59 | F17: =IF(COUNT(F5:F16)=0,"",SUM(F5:F16)) | G17: =IF(COUNT(G5:G16)=0,"",SUM(G5:G16)) -> 0.38 | H17: =IF(COUNT(H5:H16)=0,"",SUM(H5:H16)) | I17: =IF(COUNT(I5:I16)=0,"",SUM(I5:I16)) -> 0.38 | J17: =IF(I17="","",I17-(E17+N(F17))) -> -0.21 | K17: =IF(I17="","",IFERROR(I17/(E17+N(F17)),0)) -> 0.6440678 | L17: =IF(I17="","",IF(K17>=1,"Achieved","Shortfall")) -> Shortfall

Sheet 12
A1: Chandanaish Territory - Daily Sales and Target Achievement Sheet
A2: Name of Territory: | B2: Chandanaish | C2: Name of Region: | D2: Chattogram | I2: Date: | K2: 46307
A3: SL NO | B3: Name of SR / CSR | C3: Name of Route | D3: No. of Outlets | E3: Brand Wise Target | G3: Brand Wise Sales | I3: Total Sales | J3: Variance | K3: Achievement % | L3: Remarks
E4: Cigarette | F4: Bidi | G4: Cigarette | H4: Bidi
A5: =Target!A4 -> 1 | B5: =Target!B4 -> Karim | C5: =Target!C4 -> Kesua | D5: =Target!D4 | E5: =Target!G4 -> 0.05 | F5: =Target!H4 | I5: =IF(AND(G5="",H5=""),"",SUM(G5:H5)) | J5: =IF(I5="","",I5-(E5+N(F5))) | K5: =IF(I5="","",IFERROR(I5/(E5+N(F5)),0)) | L5: =IF(I5="","",IF(K5>=1.01,"Top Performer",IF(K5>=1,"Achieved",IF(K5>=0.98,"Near Target","Needs Pacing"))))
A6: =Target!A5 -> 2 | C6: =Target!C5 -> Moulvi Bazar | D6: =Target!D5 | E6: =Target!G5 -> 0.03 | F6: =Target!H5 | G6: 0.05 | I6: =IF(AND(G6="",H6=""),"",SUM(G6:H6)) -> 0.05 | J6: =IF(I6="","",I6-(E6+N(F6))) -> 0.02 | K6: =IF(I6="","",IFERROR(I6/(E6+N(F6)),0)) -> 1.6666667 | L6: =IF(I6="","",IF(K6>=1.01,"Top Performer",IF(K6>=1,"Achieved",IF(K6>=0.98,"Near Target","Needs Pacing")))) -> Top Performer
A7: =Target!A6 -> 3 | B7: =Target!B6 -> Jabed | C7: =Target!C6 -> Char Barama | D7: =Target!D6 | E7: =Target!G6 -> 0.05 | F7: =Target!H6 | G7: 0.14 | I7: =IF(AND(G7="",H7=""),"",SUM(G7:H7)) -> 0.14 | J7: =IF(I7="","",I7-(E7+N(F7))) -> 0.09 | K7: =IF(I7="","",IFERROR(I7/(E7+N(F7)),0)) -> 2.8 | L7: =IF(I7="","",IF(K7>=1.01,"Top Performer",IF(K7>=1,"Achieved",IF(K7>=0.98,"Near Target","Needs Pacing")))) -> Top Performer
A8: =Target!A7 -> 4 | C8: =Target!C7 -> Pukur Par | D8: =Target!D7 | E8: =Target!G7 -> 0.03 | F8: =Target!H7 | I8: =IF(AND(G8="",H8=""),"",SUM(G8:H8)) | J8: =IF(I8="","",I8-(E8+N(F8))) | K8: =IF(I8="","",IFERROR(I8/(E8+N(F8)),0)) | L8: =IF(I8="","",IF(K8>=1.01,"Top Performer",IF(K8>=1,"Achieved",IF(K8>=0.98,"Near Target","Needs Pacing"))))
A9: =Target!A8 -> 5 | B9: =Target!B8 -> Anowar | C9: =Target!C8 -> Dhamair Hat | D9: =Target!D8 | E9: =Target!G8 -> 0.07 | F9: =Target!H8 | G9: 0.13 | I9: =IF(AND(G9="",H9=""),"",SUM(G9:H9)) -> 0.13 | J9: =IF(I9="","",I9-(E9+N(F9))) -> 0.06 | K9: =IF(I9="","",IFERROR(I9/(E9+N(F9)),0)) -> 1.8571429 | L9: =IF(I9="","",IF(K9>=1.01,"Top Performer",IF(K9>=1,"Achieved",IF(K9>=0.98,"Near Target","Needs Pacing")))) -> Top Performer
A10: =Target!A9 -> 6 | C10: =Target!C9 -> Chomuda para | D10: =Target!D9 | E10: =Target!G9 -> 0.03 | F10: =Target!H9 | I10: =IF(AND(G10="",H10=""),"",SUM(G10:H10)) | J10: =IF(I10="","",I10-(E10+N(F10))) | K10: =IF(I10="","",IFERROR(I10/(E10+N(F10)),0)) | L10: =IF(I10="","",IF(K10>=1.01,"Top Performer",IF(K10>=1,"Achieved",IF(K10>=0.98,"Near Target","Needs Pacing"))))
A11: =Target!A10 -> 7 | B11: =Target!B10 -> Tahasin | C11: =Target!C10 -> Harala | D11: =Target!D10 | E11: =Target!G10 -> 0.05 | F11: =Target!H10 | G11: 0.04 | I11: =IF(AND(G11="",H11=""),"",SUM(G11:H11)) -> 0.04 | J11: =IF(I11="","",I11-(E11+N(F11))) -> -0.01 | K11: =IF(I11="","",IFERROR(I11/(E11+N(F11)),0)) -> 0.8 | L11: =IF(I11="","",IF(K11>=1.01,"Top Performer",IF(K11>=1,"Achieved",IF(K11>=0.98,"Near Target","Needs Pacing")))) -> Needs Pacing
A12: =Target!A11 -> 8 | C12: =Target!C11 -> Nazir Hat | D12: =Target!D11 | E12: =Target!G11 -> 0.03 | F12: =Target!H11 | I12: =IF(AND(G12="",H12=""),"",SUM(G12:H12)) | J12: =IF(I12="","",I12-(E12+N(F12))) | K12: =IF(I12="","",IFERROR(I12/(E12+N(F12)),0)) | L12: =IF(I12="","",IF(K12>=1.01,"Top Performer",IF(K12>=1,"Achieved",IF(K12>=0.98,"Near Target","Needs Pacing"))))
A13: =Target!A12 -> 9 | B13: =Target!B12 -> Amir | C13: =Target!C12 -> khan Hat | D13: =Target!D12 | E13: =Target!G12 -> 0.08 | F13: =Target!H12 | G13: 0.07 | I13: =IF(AND(G13="",H13=""),"",SUM(G13:H13)) -> 0.07 | J13: =IF(I13="","",I13-(E13+N(F13))) -> -0.01 | K13: =IF(I13="","",IFERROR(I13/(E13+N(F13)),0)) -> 0.875 | L13: =IF(I13="","",IF(K13>=1.01,"Top Performer",IF(K13>=1,"Achieved",IF(K13>=0.98,"Near Target","Needs Pacing")))) -> Needs Pacing
