Workbook
Name _FilterDatabase_1_1: #REF!
Name _FilterDatabase_1_1: #REF!
Name _FilterDatabase_1_1: #REF!
Name _FilterDatabase_1_1: #REF!
Name _FilterDatabase_1_1: #REF!
Name _FilterDatabase_1_1: #REF!
Name _FilterDatabase_1_1: #REF!
Name _FilterDatabase_1_1: #REF!
Name _FilterDatabase_1_1: #REF!
Name _FilterDatabase_1_1: #REF!
Name _FilterDatabase_1_1: #REF!
Name _FilterDatabase_1_1: #REF!
Name _FilterDatabase_1_1_1: #REF!
Name _FilterDatabase_1_1_1: #REF!
Name _FilterDatabase_1_1_1: #REF!
Name _FilterDatabase_1_1_1: #REF!
Name _FilterDatabase_1_1_1: #REF!
Name _FilterDatabase_1_1_1: #REF!
Name _FilterDatabase_1_1_1: #REF!
Name _FilterDatabase_1_1_1: #REF!
Name _FilterDatabase_1_1_1: #REF!
Name _FilterDatabase_1_1_1: #REF!
Name _FilterDatabase_1_1_1: #REF!
Name _FilterDatabase_1_1_1: #REF!
Name _FilterDatabase_1_1_1_1: #REF!
Name _FilterDatabase_1_1_1_1: #REF!
Name _FilterDatabase_1_1_1_1: #REF!
Name _FilterDatabase_1_1_1_1: #REF!
Name _FilterDatabase_1_1_1_1: #REF!
Name _FilterDatabase_1_1_1_1: #REF!
Name _FilterDatabase_1_1_1_1: #REF!
Name _FilterDatabase_1_1_1_1: #REF!
Name _FilterDatabase_1_1_1_1: #REF!
Name _FilterDatabase_1_1_1_1: #REF!
Name _FilterDatabase_1_1_1_1: #REF!
Name _FilterDatabase_1_1_1_1: #REF!
Name _FilterDatabase_1_1_1_1_1: #REF!
Name _FilterDatabase_1_1_1_1_1: #REF!
Name _FilterDatabase_1_1_1_1_1: #REF!
Name _FilterDatabase_1_1_1_1_1: #REF!
Name _FilterDatabase_1_1_1_1_1: #REF!
Name _FilterDatabase_1_1_1_1_1: #REF!
Name _FilterDatabase_1_1_1_1_1: #REF!
Name _FilterDatabase_1_1_1_1_1: #REF!
Name _FilterDatabase_1_1_1_1_1: #REF!
Name _FilterDatabase_1_1_1_1_1: #REF!
Name _FilterDatabase_1_1_1_1_1: #REF!
Name _FilterDatabase_1_1_1_1_1: #REF!
Name _FilterDatabase_1_1_1_1_1_1: #REF!
Name _FilterDatabase_1_1_1_1_1_1: #REF!
Name _FilterDatabase_1_1_1_1_1_1: #REF!
Name _FilterDatabase_1_1_1_1_1_1: #REF!
Name _FilterDatabase_1_1_1_1_1_1: #REF!
Name _FilterDatabase_1_1_1_1_1_1: #REF!
Name _FilterDatabase_1_1_1_1_1_1: #REF!
Name _FilterDatabase_1_1_1_1_1_1: #REF!
Name _FilterDatabase_1_1_1_1_1_1: #REF!
Name _FilterDatabase_1_1_1_1_1_1: #REF!
Name _FilterDatabase_1_1_1_1_1_1: #REF!
Name _FilterDatabase_1_1_1_1_1_1: #REF!

Sheet 1
A1: Afaz Tobacco Company .
A2: Marketing Department
A3: Month:October-2026
A4: Daily Sales & Closing Stock Information.
B5: Date:01.10.2026 | G5: Division: Ctg South | U5: Wing: Chittagong
A6: SL. NO | B6: Name of Region | C6: Name of Territory | D6: Brand wise Sales (BITCL) | J6: TOTAL SALES | K6: Brand Wise Closing Stock (BITCL) | Q6: TOTAL Stock | R6: Brand wise Sales (BITCL) | W6: Total Zarda Sales Value | X6: Brand Wise Closing Stock (BITCL) | AC6: Total Zarda C.Stock Value | AD6: Express Empty Packet | AE6: Remark
D7: Wilson | E7: Shahara | F7: Express | G7: Nexus | H7: SB | I7: SM | K7: Wilson | L7: Shahara | M7: Express | N7: Nexus | O7: SB | P7: SM | R7: SLB | S7: 22/25 | T7: 99/14 | U7: 33/15 | X7: SLB | Y7: 22/25 | Z7: 99/14 | AA7: 33/15
A8: 1 | B8: Satkania | C8: Kerani hat | D8: 0 | E8: 0 | F8: 0.68 | G8: 0 | H8: 0 | I8: 0 | J8: =SUM(D8:I8) -> 0.68 | K8: 0.19 | L8: 0 | M8: 0.84 | N8: 0 | O8: 0 | P8: 0 | Q8: =SUM(K8:P8) -> 1.03 | R8: 0.01 | S8: 5 | T8: 0 | U8: 0 | V8: 0 | W8: =S8*15+T8*6+U8*8 -> 75 | X8: 0.97 | Y8: 1298 | Z8: 0 | AA8: 0 | AB8: 0 | AC8: =Y8*15+Z8*6+AA8*8 -> 19470 | AD8: 6660
A9: 2 | C9: Satkania | D9: 0.01 | E9: 0 | F9: 0.41 | G9: 0 | H9: 0 | I9: 0 | J9: =SUM(D9:I9) -> 0.42 | K9: 0.05 | L9: 0 | M9: 1.15 | N9: 0 | O9: 0 | P9: 0 | Q9: =SUM(K9:P9) -> 1.2 | R9: 0.01 | S9: 10 | T9: 0 | U9: 0 | V9: 0 | W9: =S9*15+T9*6+U9*8 -> 150 | X9: 0.63 | Y9: 363 | Z9: 0 | AA9: 0 | AB9: 0 | AC9: =Y9*15+Z9*6+AA9*8 -> 5445 | AD9: 4270
A10: 3 | C10: Bandarban | D10: 0 | E10: 0 | F10: 0.42 | G10: 0 | H10: 0 | I10: 0 | J10: =SUM(D10:I10) -> 0.42 | K10: 0.22 | L10: 0 | M10: 2.71 | N10: 0 | O10: 0 | P10: 0 | Q10: 2.93 | R10: 0.03 | S10: 0 | T10: 60 | U10: 0 | V10: 0 | W10: =S10*15+T10*6+U10*8 -> 360 | X10: 1.15 | Y10: 60 | Z10: 1134 | AA10: 0 | AB10: 0 | AC10: =Y10*15+Z10*6+AA10*8 -> 7704 | AD10: 4050
A11: 4 | C11: Rajasthali | D11: 0 | E11: 0 | F11: 0.06 | G11: 0 | H11: 0 | I11: 0 | J11: =SUM(D11:I11) -> 0.06 | K11: 0.09 | L11: 0 | M11: 0.11 | N11: 0 | O11: 0 | P11: 0 | Q11: =SUM(K11:P11) -> 0.2 | R11: 0.01 | S11: 0 | T11: 0 | U11: 0 | V11: 0 | W11: =S11*15+T11*6+U11*8 -> 0 | X11: 0.11 | Y11: 0 | Z11: 0 | AA11: 0 | AB11: 0 | AC11: =Y11*15+Z11*6+AA11*8 -> 0 | AD11: 600
A12: 5 | C12: Dohazari | D12: 0 | E12: 0 | F12: 0.62 | G12: 0 | H12: 0 | I12: 0 | J12: =SUM(D12:I12) -> 0.62 | K12: 0.1 | L12: 0 | M12: 3.82 | N12: 0 | O12: 0 | P12: 0 | Q12: =SUM(K12:P12) -> 3.92 | R12: 0 | S12: 18 | T12: 0 | U12: 0 | V12: 0 | W12: =S12*15+T12*6+U12*8 -> 270 | X12: 0.58 | Y12: 962 | AA12: 0 | AB12: 0 | AC12: =Y12*15+Z12*6+AA12*8 -> 14430 | AD12: 6400
A13: Satkania Region Total | D13: =SUM(D8:D12) -> 0.01 | E13: =SUM(E8:E12) -> 0 | F13: =SUM(F8:F12) -> 2.19 | G13: =SUM(G8:G12) -> 0 | H13: =SUM(H8:H12) -> 0 | I13: =SUM(I8:I12) -> 0 | J13: =SUM(J8:J12) -> 2.2 | K13: =SUM(K8:K12) -> 0.65 | ... AD13: =SUM(AD8:AD12) -> 21980

Sheet 2
A1: ='1'!A1 -> Afaz Tobacco Company .
A2: ='1'!A2 -> Marketing Department
A3: Month:October-2026
A4: ='1'!A4 -> Daily Sales & Closing Stock Information.
B5: Date:02.10.2026 | G5: Division: Ctg South | U5: Wing: Chittagong
A6: SL. NO | B6: Name of Region | C6: Name of Territory | D6: Brand wise Sales (BITCL) | J6: TOTAL SALES | K6: Brand Wise Closing Stock (BITCL) | Q6: TOTAL Stock | R6: Brand wise Sales (BITCL) | W6: Total Zarda Sales Value | X6: Brand Wise Closing Stock (BITCL) | AC6: Total Zarda C.Stock Value | AD6: Express Empty Packet | AE6: Remark
D7: Wilson | E7: Shahara | F7: Express | G7: Nexus | H7: SB | I7: SM | K7: Wilson | L7: Shahara | M7: Express | N7: Nexus | O7: SB | P7: SM | R7: SLB | S7: 22/25 | T7: 99/14 | U7: 33/15 | X7: SLB | Y7: 22/25 | Z7: 99/14 | AA7: 33/15
A8: 1 | B8: Satkania | C8: Kerani hat | D8: 0 | E8: 0 | F8: 0 | G8: 0 | H8: 0 | I8: 0 | J8: =SUM(D8:I8) -> 0 | K8: 0 | L8: 0 | M8: 0 | N8: 0 | O8: 0 | P8: 0 | Q8: =SUM(K8:P8) -> 0 | R8: 0 | S8: 0 | T8: 0 | U8: 0 | V8: 0 | W8: =S8*15+T8*6+U8*8 -> 0 | X8: 0 | Y8: 0 | Z8: 0 | AA8: 0 | AB8: 0 | AC8: =Y8*15+Z8*6+AA8*8 -> 0 | AD8: 0
A9: 2 | C9: Satkania | D9: 0 | E9: 0 | F9: 0 | G9: 0 | H9: 0 | I9: 0 | J9: =SUM(D9:I9) -> 0 | K9: 0 | L9: 0 | M9: 0 | N9: 0 | O9: 0 | P9: 0 | Q9: =SUM(K9:P9) -> 0 | R9: 0 | S9: 0 | T9: 0 | U9: 0 | V9: 0 | W9: =S9*15+T9*6+U9*8 -> 0 | X9: 0 | Y9: 0 | Z9: 0 | AA9: 0 | AB9: 0 | AC9: =Y9*15+Z9*6+AA9*8 -> 0 | AD9: 0
A10: 3 | C10: Bandarban | D10: 0 | E10: 0 | F10: 0 | G10: 0 | H10: 0 | I10: 0 | J10: =SUM(D10:I10) -> 0 | K10: 0 | L10: 0 | M10: 0 | N10: 0 | O10: 0 | P10: 0 | Q10: =SUM(K10:P10) -> 0 | R10: 0 | S10: 0 | T10: 0 | U10: 0 | V10: 0 | W10: =S10*15+T10*6+U10*8 -> 0 | X10: 0 | Y10: 0 | Z10: 0 | AA10: 0 | AB10: 0 | AC10: =Y10*15+Z10*6+AA10*8 -> 0 | AD10: 0
A11: 4 | C11: Rajasthali | D11: 0 | E11: 0 | F11: 0 | G11: 0 | H11: 0 | I11: 0 | J11: =SUM(D11:I11) -> 0 | K11: 0 | L11: 0 | M11: 0 | N11: 0 | O11: 0 | P11: 0 | Q11: =SUM(K11:P11) -> 0 | R11: 0 | S11: 0 | T11: 0 | U11: 0 | V11: 0 | W11: =S11*15+T11*6+U11*8 -> 0 | X11: 0 | Y11: 0 | Z11: 0 | AA11: 0 | AB11: 0 | AC11: =Y11*15+Z11*6+AA11*8 -> 0 | AD11: 0
A12: 5 | C12: Dohazari | D12: 0 | E12: 0 | F12: 0 | G12: 0 | H12: 0 | I12: 0 | J12: =SUM(D12:I12) -> 0 | K12: 0 | L12: 0 | M12: 0 | N12: 0 | O12: 0 | P12: 0 | Q12: =SUM(K12:P12) -> 0 | R12: 0 | S12: 0 | T12: 0 | U12: 0 | V12: 0 | W12: =S12*15+T12*6+U12*8 -> 0 | X12: 0 | Y12: 0 | Z12: 0 | AA12: 0 | AB12: 0 | AC12: =Y12*15+Z12*6+AA12*8 -> 0 | AD12: 0
A13: Satkania Region Total | D13: =SUM(D8:D12) -> 0 | E13: =SUM(E8:E12) -> 0 | F13: =SUM(F8:F12) -> 0 | G13: =SUM(G8:G12) -> 0 | H13: =SUM(H8:H12) -> 0 | I13: =SUM(I8:I12) -> 0 | J13: =SUM(J8:J12) -> 0 | K13: =SUM(K8:K12) -> 0 | ... AD13: =SUM(AD8:AD12) -> 0

Sheet 3
A1: ='1'!A1 -> Afaz Tobacco Company .
A2: ='1'!A2 -> Marketing Department
A3: Month:October-2026
A4: ='1'!A4 -> Daily Sales & Closing Stock Information.
B5: Date:03.10.2026 | G5: Division: Ctg South | U5: Wing: Chittagong
A6: SL. NO | B6: Name of Region | C6: Name of Territory | D6: Brand wise Sales (BITCL) | J6: TOTAL SALES | K6: Brand Wise Closing Stock (BITCL) | Q6: TOTAL Stock | R6: Brand wise Sales (BITCL) | W6: Total Zarda Sales Value | X6: Brand Wise Closing Stock (BITCL) | AC6: Total Zarda C.Stock Value | AD6: Express Empty Packet | AE6: Remark
D7: Wilson | E7: Shahara | F7: Express | G7: Nexus | H7: SB | I7: SM | K7: Wilson | L7: Shahara | M7: Express | N7: Nexus | O7: SB | P7: SM | R7: SLB | S7: 22/25 | T7: 99/14 | U7: 33/15 | X7: SLB | Y7: 22/25 | Z7: 99/14 | AA7: 33/15
A8: 1 | B8: Satkania | C8: Kerani hat | D8: 0 | E8: 0 | F8: 0.68 | G8: 0 | H8: 0 | I8: 0 | J8: =SUM(D8:I8) -> 0.68 | K8: 0.19 | L8: 0 | M8: 2.16 | N8: 0 | O8: 0 | P8: 0 | Q8: =SUM(K8:P8) -> 2.35 | R8: 0 | S8: 28 | T8: 0 | U8: 0 | V8: 0 | W8: =S8*15+T8*6+U8*8 -> 420 | X8: 1 | Y8: 1215 | Z8: 0 | AA8: 0 | AB8: 0 | AC8: =Y8*15+Z8*6+AA8*8 -> 18225 | AD8: 11760
A9: 2 | C9: Satkania | D9: 0 | E9: 0 | F9: 0.52 | G9: 0 | H9: 0 | I9: 0 | J9: =SUM(D9:I9) -> 0.52 | K9: 0.05 | L9: 0 | M9: 2.63 | N9: 0 | O9: 0 | P9: 0 | Q9: =SUM(K9:P9) -> 2.68 | R9: 0 | S9: 30 | T9: 0 | U9: 0 | V9: 0 | W9: =S9*15+T9*6+U9*8 -> 450 | X9: 0.63 | Y9: 333 | Z9: 0 | AA9: 0 | AB9: 0 | AC9: =Y9*15+Z9*6+AA9*8 -> 4995 | AD9: 8500
A10: 3 | C10: Bandarban | D10: 0 | E10: 0 | F10: 0.4 | G10: 0 | H10: 0 | I10: 0 | J10: =SUM(D10:I10) -> 0.4 | K10: 0.22 | L10: 0 | M10: 2.11 | N10: 0 | O10: 0 | P10: 0 | Q10: =SUM(K10:P10) -> 2.33 | R10: 0.03 | S10: 0 | T10: 66 | U10: 0 | V10: 0 | W10: =S10*15+T10*6+U10*8 -> 396 | X10: 1.13 | Y10: 60 | Z10: 1070 | AA10: 0 | AB10: 0 | AC10: =Y10*15+Z10*6+AA10*8 -> 7320 | AD10: 4800
A11: 4 | C11: Rajasthali | D11: 0 | E11: 0 | F11: 0.07 | G11: 0 | H11: 0 | I11: 0 | J11: =SUM(D11:I11) -> 0.07 | K11: 0.09 | L11: 0 | M11: 0.04 | N11: 0 | O11: 0 | P11: 0 | Q11: =SUM(K11:P11) -> 0.13 | R11: 0.01 | S11: 0 | T11: 0 | U11: 0 | V11: 0 | W11: =S11*15+T11*6+U11*8 -> 0 | X11: 0.1 | Y11: 0 | Z11: 0 | AA11: 0 | AB11: 0 | AC11: =Y11*15+Z11*6+AA11*8 -> 0 | AD11: 1000
A12: 5 | C12: Dohazari | D12: 0 | E12: 0 | F12: 0.57 | G12: 0 | H12: 0 | I12: 0 | J12: =SUM(D12:I12) -> 0.57 | K12: 0.1 | L12: 0 | M12: 3.25 | N12: 0 | O12: 0 | P12: 0 | Q12: =SUM(K12:P12) -> 3.35 | R12: 0 | S12: 54 | T12: 0 | U12: 0 | V12: 0 | W12: =S12*15+T12*6+U12*8 -> 810 | X12: 0.58 | Y12: 908 | Z12: 0 | AA12: 0 | AB12: 0 | AC12: =Y12*15+Z12*6+AA12*8 -> 13620 | AD12: 7450
A13: Satkania Region Total | D13: =SUM(D8:D12) -> 0 | E13: =SUM(E8:E12) -> 0 | F13: =SUM(F8:F12) -> 2.24 | G13: =SUM(G8:G12) -> 0 | H13: =SUM(H8:H12) -> 0 | I13: =SUM(I8:I12) -> 0 | J13: =SUM(J8:J12) -> 2.24 | K13: =SUM(K8:K12) -> 0.65 | ... AD13: =SUM(AD8:AD12) -> 33510

Sheet 4
A1: ='1'!A1 -> Afaz Tobacco Company .
A2: ='1'!A2 -> Marketing Department
A3: Month:October-2026
A4: ='1'!A4 -> Daily Sales & Closing Stock Information.
B5: Date:04.10.2026 | G5: Division: Ctg South | U5: Wing: Chittagong
A6: SL. NO | B6: Name of Region | C6: Name of Territory | D6: Brand wise Sales (BITCL) | J6: TOTAL SALES | K6: Brand Wise Closing Stock (BITCL) | Q6: TOTAL Stock | R6: Brand wise Sales (BITCL) | W6: Total Zarda Sales Value | X6: Brand Wise Closing Stock (BITCL) | AC6: Total Zarda C.Stock Value | AD6: Express Empty Packet | AE6: Remark
D7: Wilson | E7: Shahara | F7: Express | G7: Nexus | H7: SB | I7: SM | K7: Wilson | L7: Shahara | M7: Express | N7: Nexus | O7: SB | P7: SM | R7: SLB | S7: 22/25 | T7: 99/14 | U7: 33/15 | X7: SLB | Y7: 22/25 | Z7: 99/14 | AA7: 33/15
A8: 1 | B8: Satkania | C8: Kerani hat | D8: 0 | E8: 0 | F8: 0.65 | G8: 0 | H8: 0 | I8: 0 | J8: =SUM(D8:I8) -> 0.65 | K8: 0.19 | L8: 0 | M8: 1.51 | N8: 0 | O8: 0 | P8: 0 | Q8: =SUM(K8:P8) -> 1.7 | R8: 0.01 | S8: 22 | T8: 0 | U8: 0 | V8: 0 | W8: =S8*15+T8*6+U8*8 -> 330 | X8: 0.99 | Y8: 1193 | Z8: 0 | AA8: 0 | AB8: 0 | AC8: =Y8*15+Z8*6+AA8*8 -> 17895 | AD8: 8720
A9: 2 | C9: Satkania | D9: 0.01 | E9: 0 | F9: 0.59 | G9: 0 | H9: 0 | I9: 0 | J9: =SUM(D9:I9) -> 0.6 | K9: 0.04 | L9: 0 | M9: 2.04 | N9: 0 | O9: 0 | P9: 0 | Q9: =SUM(K9:P9) -> 2.08 | R9: 0 | S9: 30 | T9: 0 | U9: 0 | V9: 0 | W9: =S9*15+T9*6+U9*8 -> 450 | X9: 0.63 | Y9: 303 | Z9: 0 | AA9: 0 | AB9: 0 | AC9: =Y9*15+Z9*6+AA9*8 -> 4545 | AD9: 8920
A10: 3 | C10: Bandarban | D10: 0 | E10: 0 | F10: 0.45 | G10: 0 | H10: 0 | I10: 0 | J10: =SUM(D10:I10) -> 0.45 | K10: 0.22 | L10: 0 | M10: 1.66 | N10: 0 | O10: 0 | P10: 0 | Q10: =SUM(K10:P10) -> 1.88 | R10: 0.1 | S10: 0 | T10: 12 | U10: 0 | V10: 0 | W10: =S10*15+T10*6+U10*8 -> 72 | X10: 1.03 | Y10: 0 | Z10: 1058 | AA10: 0 | AB10: 0 | AC10: =Y10*15+Z10*6+AA10*8 -> 6348 | AD10: 6700
A11: 4 | C11: Rajasthali | D11: 0 | E11: 0 | F11: 0.06 | G11: 0 | H11: 0 | I11: 0 | J11: =SUM(D11:I11) -> 0.06 | K11: 0 | L11: 0 | M11: 0.18 | N11: 0 | O11: 0 | P11: 0 | Q11: =SUM(K11:P11) -> 0.18 | R11: 0.01 | S11: 0 | T11: 0 | U11: 0 | V11: 0 | W11: =S11*15+T11*6+U11*8 -> 0 | X11: 0.09 | Y11: 0 | Z11: 0 | AA11: 0 | AB11: 0 | AC11: =Y11*15+Z11*6+AA11*8 -> 0 | AD11: 600
A12: 5 | C12: Dohazari | D12: 0 | E12: 0 | F12: 0.6 | G12: 0 | H12: 0 | I12: 0 | J12: =SUM(D12:I12) -> 0.6 | K12: 0.1 | L12: 0 | M12: 2.65 | N12: 0 | O12: 0 | P12: 0 | Q12: =SUM(K12:P12) -> 2.75 | R12: 0 | S12: 36 | T12: 0 | U12: 0 | V12: 0 | W12: =S12*15+T12*6+U12*8 -> 540 | X12: 0.58 | Y12: 872 | Z12: 0 | AA12: 0 | AB12: 0 | AC12: =Y12*15+Z12*6+AA12*8 -> 13080 | AD12: 7700
A13: Satkania Region Total | D13: =SUM(D8:D12) -> 0.01 | E13: =SUM(E8:E12) -> 0 | F13: =SUM(F8:F12) -> 2.35 | G13: =SUM(G8:G12) -> 0 | H13: =SUM(H8:H12) -> 0 | I13: =SUM(I8:I12) -> 0 | J13: =SUM(J8:J12) -> 2.36 | K13: =SUM(K8:K12) -> 0.55 | ... AD13: =SUM(AD8:AD12) -> 32640

Sheet 5
A1: ='1'!A1 -> Afaz Tobacco Company .
A2: ='1'!A2 -> Marketing Department
A3: Month:October-2026
A4: ='1'!A4 -> Daily Sales & Closing Stock Information.
B5: Date:05.10.2026 | G5: Division: Ctg South | U5: Wing: Chittagong
A6: SL. NO | B6: Name of Region | C6: Name of Territory | D6: Brand wise Sales (BITCL) | J6: TOTAL SALES | K6: Brand Wise Closing Stock (BITCL) | Q6: TOTAL Stock | R6: Brand wise Sales (BITCL) | W6: Total Zarda Sales Value | X6: Brand Wise Closing Stock (BITCL) | AC6: Total Zarda C.Stock Value | AD6: Express Empty Packet | AE6: Remark
D7: Wilson | E7: Shahara | F7: Express | G7: Nexus | H7: SB | I7: SM | K7: Wilson | L7: Shahara | M7: Express | N7: Nexus | O7: SB | P7: SM | R7: SLB | S7: 22/25 | T7: 99/14 | U7: 33/15 | X7: SLB | Y7: 22/25 | Z7: 99/14 | AA7: 33/15
A8: 1 | B8: Satkania | C8: Kerani hat | D8: 0.01 | E8: 0 | F8: 0.5 | G8: 0 | H8: 0 | I8: 0 | J8: =SUM(D8:I8) -> 0.51 | K8: 0.18 | L8: 0 | M8: 1.01 | N8: 0 | O8: 0 | P8: 0 | Q8: =SUM(K8:P8) -> 1.19 | R8: 0.01 | S8: 22 | T8: 0 | U8: 0 | V8: 0 | W8: =S8*15+T8*6+U8*8 -> 330 | X8: 0.98 | Y8: 1171 | Z8: 0 | AA8: 0 | AB8: 0 | AC8: =Y8*15+Z8*6+AA8*8 -> 17565 | AD8: 8190
A9: 2 | C9: Satkania | D9: 0.01 | E9: 0 | F9: 0.54 | G9: 0 | H9: 0 | I9: 0 | J9: =SUM(D9:I9) -> 0.55 | K9: 0.03 | L9: 0 | M9: 1.5 | N9: 0 | O9: 0 | P9: 0 | Q9: =SUM(K9:P9) -> 1.53 | R9: 0.01 | S9: 33 | T9: 0 | U9: 0 | V9: 0 | W9: =S9*15+T9*6+U9*8 -> 495 | X9: 0.62 | Y9: 270 | Z9: 0 | AA9: 0 | AB9: 0 | AC9: =Y9*15+Z9*6+AA9*8 -> 4050 | AD9: 7180
A10: 3 | C10: Bandarban | D10: 0 | E10: 0 | F10: 0 | G10: 0 | H10: 0 | I10: 0 | J10: =SUM(D10:I10) -> 0 | K10: 0 | L10: 0 | M10: 0 | N10: 0 | O10: 0 | P10: 0 | Q10: =SUM(K10:P10) -> 0 | R10: 0 | S10: 0 | T10: 0 | U10: 0 | V10: 0 | W10: =S10*15+T10*6+U10*8 -> 0 | X10: 0 | Y10: 0 | Z10: 0 | AA10: 0 | AB10: 0 | AC10: =Y10*15+Z10*6+AA10*8 -> 0 | AD10: 0
A11: 4 | C11: Rajasthali | D11: 0 | E11: 0 | F11: 0.07 | G11: 0 | H11: 0 | I11: 0 | J11: =SUM(D11:I11) -> 0.07 | K11: 0.09 | L11: 0 | M11: 0.11 | N11: 0 | O11: 0 | P11: 0 | Q11: =SUM(K11:P11) -> 0.2 | R11: 0.01 | S11: 0 | T11: 0 | U11: 0 | V11: 0 | W11: =S11*15+T11*6+U11*8 -> 0 | X11: 0.08 | Y11: 0 | Z11: 0 | AA11: 0 | AB11: 0 | AC11: =Y11*15+Z11*6+AA11*8 -> 0 | AD11: 500
A12: 5 | C12: Dohazari | D12: 0.01 | E12: 0 | F12: 0.6 | G12: 0 | H12: 0 | I12: 0 | J12: =SUM(D12:I12) -> 0.61 | K12: 0.09 | L12: 0 | M12: 2.05 | N12: 0 | O12: 0 | P12: 0 | Q12: =SUM(K12:P12) -> 2.14 | R12: 0 | S12: 60 | T12: 0 | U12: 0 | V12: 0 | W12: =S12*15+T12*6+U12*8 -> 900 | X12: 0.58 | Y12: 812 | Z12: 0 | AA12: 0 | AB12: 0 | AC12: =Y12*15+Z12*6+AA12*8 -> 12180 | AD12: 6390
A13: Satkania Region Total | D13: =SUM(D8:D12) -> 0.03 | E13: =SUM(E8:E12) -> 0 | F13: =SUM(F8:F12) -> 1.71 | G13: =SUM(G8:G12) -> 0 | H13: =SUM(H8:H12) -> 0 | I13: =SUM(I8:I12) -> 0 | J13: =SUM(J8:J12) -> 1.74 | K13: =SUM(K8:K12) -> 0.39 | ... AD13: =SUM(AD8:AD12) -> 22260

Sheet 6
A1: ='1'!A1 -> Afaz Tobacco Company .
A2: ='1'!A2 -> Marketing Department
A3: Month:October-2026
A4: ='1'!A4 -> Daily Sales & Closing Stock Information.
B5: Date:06.10.2026 | G5: Division: Ctg South | U5: Wing: Chittagong
A6: SL. NO | B6: Name of Region | C6: Name of Territory | D6: Brand wise Sales (BITCL) | J6: TOTAL SALES | K6: Brand Wise Closing Stock (BITCL) | Q6: TOTAL Stock | R6: Brand wise Sales (BITCL) | W6: Total Zarda Sales Value | X6: Brand Wise Closing Stock (BITCL) | AC6: Total Zarda C.Stock Value | AD6: Express Empty Packet | AE6: Remark
D7: Wilson | E7: Shahara | F7: Express | G7: Nexus | H7: SB | I7: SM | K7: Wilson | L7: Shahara | M7: Express | N7: Nexus | O7: SB | P7: SM | R7: SLB | S7: 22/25 | T7: 99/14 | U7: 33/15 | X7: SLB | Y7: 22/25 | Z7: 99/14 | AA7: 33/15
A8: 1 | B8: Satkania | C8: Kerani hat | D8: 0 | E8: 0 | F8: 0 | G8: 0 | H8: 0 | I8: 0 | J8: =SUM(D8:I8) -> 0 | K8: 0 | L8: 0 | M8: 0 | N8: 0 | O8: 0 | P8: 0 | Q8: =SUM(K8:P8) -> 0 | R8: 0 | S8: 0 | T8: 0 | U8: 0 | V8: 0 | W8: =S8*15+T8*6+U8*8 -> 0 | X8: 0 | Y8: 0 | Z8: 0 | AA8: 0 | AB8: 0 | AC8: =Y8*15+Z8*6+AA8*8 -> 0 | AD8: 0
A9: 2 | C9: Satkania | D9: 0 | E9: 0 | F9: 0 | G9: 0 | H9: 0 | I9: 0 | J9: =SUM(D9:I9) -> 0 | K9: 0 | L9: 0 | M9: 0 | N9: 0 | O9: 0 | P9: 0 | Q9: =SUM(K9:P9) -> 0 | R9: 0 | S9: 0 | T9: 0 | U9: 0 | V9: 0 | W9: =S9*15+T9*6+U9*8 -> 0 | X9: 0 | Y9: 0 | Z9: 0 | AA9: 0 | AB9: 0 | AC9: =Y9*15+Z9*6+AA9*8 -> 0 | AD9: 0
A10: 3 | C10: Bandarban | D10: 0 | E10: 0 | F10: 0 | G10: 0 | H10: 0 | I10: 0 | J10: =SUM(D10:I10) -> 0 | K10: 0 | L10: 0 | M10: 0 | N10: 0 | O10: 0 | P10: 0 | Q10: =SUM(K10:P10) -> 0 | R10: 0 | S10: 0 | T10: 0 | U10: 0 | V10: 0 | W10: =S10*15+T10*6+U10*8 -> 0 | X10: 0 | Y10: 0 | Z10: 0 | AA10: 0 | AB10: 0 | AC10: =Y10*15+Z10*6+AA10*8 -> 0 | AD10: 0
A11: 4 | C11: Rajasthali | D11: 0 | E11: 0 | F11: 0 | G11: 0 | H11: 0 | I11: 0 | J11: =SUM(D11:I11) -> 0 | K11: 0 | L11: 0 | M11: 0 | N11: 0 | O11: 0 | P11: 0 | Q11: =SUM(K11:P11) -> 0 | R11: 0 | S11: 0 | T11: 0 | U11: 0 | V11: 0 | W11: =S11*15+T11*6+U11*8 -> 0 | X11: 0 | Y11: 0 | Z11: 0 | AA11: 0 | AB11: 0 | AC11: =Y11*15+Z11*6+AA11*8 -> 0 | AD11: 0
A12: 5 | C12: Dohazari | D12: 0 | E12: 0 | F12: 0 | G12: 0 | H12: 0 | I12: 0 | J12: =SUM(D12:I12) -> 0 | K12: 0 | L12: 0 | M12: 0 | N12: 0 | O12: 0 | P12: 0 | Q12: =SUM(K12:P12) -> 0 | R12: 0 | S12: 0 | T12: 0 | U12: 0 | V12: 0 | W12: =S12*15+T12*6+U12*8 -> 0 | X12: 0 | Y12: 0 | Z12: 0 | AA12: 0 | AB12: 0 | AC12: =Y12*15+Z12*6+AA12*8 -> 0 | AD12: 0
A13: Satkania Region Total | D13: =SUM(D8:D12) -> 0 | E13: =SUM(E8:E12) -> 0 | F13: =SUM(F8:F12) -> 0 | G13: =SUM(G8:G12) -> 0 | H13: =SUM(H8:H12) -> 0 | I13: =SUM(I8:I12) -> 0 | J13: =SUM(J8:J12) -> 0 | K13: =SUM(K8:K12) -> 0 | ... AD13: =SUM(AD8:AD12) -> 0

Sheet 7
A1: ='1'!A1 -> Afaz Tobacco Company .
A2: ='1'!A2 -> Marketing Department
A3: Month:October-2026
A4: ='1'!A4 -> Daily Sales & Closing Stock Information.
B5: Date:07.10.2026 | G5: Division: Ctg South | U5: Wing: Chittagong
A6: SL. NO | B6: Name of Region | C6: Name of Territory | D6: Brand wise Sales (BITCL) | J6: TOTAL SALES | K6: Brand Wise Closing Stock (BITCL) | Q6: TOTAL Stock | R6: Brand wise Sales (BITCL) | W6: Total Zarda Sales Value | X6: Brand Wise Closing Stock (BITCL) | AC6: Total Zarda C.Stock Value | AD6: Express Empty Packet | AE6: Remark
D7: Wilson | E7: Shahara | F7: Express | G7: Nexus | H7: SB | I7: SM | K7: Wilson | L7: Shahara | M7: Express | N7: Nexus | O7: SB | P7: SM | R7: SLB | S7: 22/25 | T7: 99/14 | U7: 33/15 | X7: SLB | Y7: 22/25 | Z7: 99/14 | AA7: 33/15
A8: 1 | B8: Satkania | C8: Kerani hat | D8: 0 | E8: 0 | F8: 0 | G8: 0 | H8: 0 | I8: 0 | J8: =SUM(D8:I8) -> 0 | K8: 0 | L8: 0 | M8: 0 | N8: 0 | O8: 0 | P8: 0 | Q8: =SUM(K8:P8) -> 0 | R8: 0 | S8: 0 | T8: 0 | U8: 0 | V8: 0 | W8: =S8*15+T8*6+U8*8 -> 0 | X8: 0 | Y8: 0 | Z8: 0 | AA8: 0 | AB8: 0 | AC8: =Y8*15+Z8*6+AA8*8 -> 0 | AD8: 0
A9: 2 | C9: Satkania | D9: 0 | E9: 0 | F9: 0 | G9: 0 | H9: 0 | I9: 0 | J9: =SUM(D9:I9) -> 0 | K9: 0 | L9: 0 | M9: 0 | N9: 0 | O9: 0 | P9: 0 | Q9: =SUM(K9:P9) -> 0 | R9: 0 | S9: 0 | T9: 0 | U9: 0 | V9: 0 | W9: =S9*15+T9*6+U9*8 -> 0 | X9: 0 | Y9: 0 | Z9: 0 | AA9: 0 | AB9: 0 | AC9: =Y9*15+Z9*6+AA9*8 -> 0 | AD9: 0
A10: 3 | C10: Bandarban | D10: 0 | E10: 0 | F10: 0 | G10: 0 | H10: 0 | I10: 0 | J10: =SUM(D10:I10) -> 0 | K10: 0 | L10: 0 | M10: 0 | N10: 0 | O10: 0 | P10: 0 | Q10: =SUM(K10:P10) -> 0 | R10: 0 | S10: 0 | T10: 0 | U10: 0 | V10: 0 | W10: =S10*15+T10*6+U10*8 -> 0 | X10: 0 | Y10: 0 | Z10: 0 | AA10: 0 | AB10: 0 | AC10: =Y10*15+Z10*6+AA10*8 -> 0 | AD10: 0
A11: 4 | C11: Rajasthali | D11: 0 | E11: 0 | F11: 0 | G11: 0 | H11: 0 | I11: 0 | J11: =SUM(D11:I11) -> 0 | K11: 0 | L11: 0 | M11: 0 | N11: 0 | O11: 0 | P11: 0 | Q11: =SUM(K11:P11) -> 0 | R11: 0 | S11: 0 | T11: 0 | U11: 0 | V11: 0 | W11: =S11*15+T11*6+U11*8 -> 0 | X11: 0 | Y11: 0 | Z11: 0 | AA11: 0 | AB11: 0 | AC11: =Y11*15+Z11*6+AA11*8 -> 0 | AD11: 0
A12: 5 | C12: Dohazari | D12: 0 | E12: 0 | F12: 0 | G12: 0 | H12: 0 | I12: 0 | J12: =SUM(D12:I12) -> 0 | K12: 0 | L12: 0 | M12: 0 | N12: 0 | O12: 0 | P12: 0 | Q12: =SUM(K12:P12) -> 0 | R12: 0 | S12: 0 | T12: 0 | U12: 0 | V12: 0 | W12: =S12*15+T12*6+U12*8 -> 0 | X12: 0 | Y12: 0 | Z12: 0 | AA12: 0 | AB12: 0 | AC12: =Y12*15+Z12*6+AA12*8 -> 0 | AD12: 0
A13: Satkania Region Total | D13: =SUM(D8:D12) -> 0 | E13: =SUM(E8:E12) -> 0 | F13: =SUM(F8:F12) -> 0 | G13: =SUM(G8:G12) -> 0 | H13: =SUM(H8:H12) -> 0 | I13: =SUM(I8:I12) -> 0 | J13: =SUM(J8:J12) -> 0 | K13: =SUM(K8:K12) -> 0 | ... AD13: =SUM(AD8:AD12) -> 0

Sheet 8
A1: ='1'!A1 -> Afaz Tobacco Company .
A2: ='1'!A2 -> Marketing Department
A3: Month:October-2026
A4: ='1'!A4 -> Daily Sales & Closing Stock Information.
B5: Date:08.10.2026 | G5: Division: Ctg South | U5: Wing: Chittagong
A6: SL. NO | B6: Name of Region | C6: Name of Territory | D6: Brand wise Sales (BITCL) | J6: TOTAL SALES | K6: Brand Wise Closing Stock (BITCL) | Q6: TOTAL Stock | R6: Brand wise Sales (BITCL) | W6: Total Zarda Sales Value | X6: Brand Wise Closing Stock (BITCL) | AC6: Total Zarda C.Stock Value | AD6: Express Empty Packet | AE6: Remark
D7: Wilson | E7: Shahara | F7: Express | G7: Nexus | H7: SB | I7: SM | K7: Wilson | L7: Shahara | M7: Express | N7: Nexus | O7: SB | P7: SM | R7: SLB | S7: 22/25 | T7: 99/14 | U7: 33/15 | X7: SLB | Y7: 22/25 | Z7: 99/14 | AA7: 33/15
A8: 1 | B8: Satkania | C8: Kerani hat | D8: 0 | E8: 0 | F8: 0 | G8: 0 | H8: 0 | I8: 0 | J8: =SUM(D8:I8) -> 0 | K8: 0 | L8: 0 | M8: 0 | N8: 0 | O8: 0 | P8: 0 | Q8: =SUM(K8:P8) -> 0 | R8: 0 | S8: 0 | T8: 0 | U8: 0 | V8: 0 | W8: =S8*15+T8*6+U8*8 -> 0 | X8: 0 | Y8: 0 | Z8: 0 | AA8: 0 | AB8: 0 | AC8: =Y8*15+Z8*6+AA8*8 -> 0 | AD8: 0
A9: 2 | C9: Satkania | D9: 0 | E9: 0 | F9: 0 | G9: 0 | H9: 0 | I9: 0 | J9: =SUM(D9:I9) -> 0 | K9: 0 | L9: 0 | M9: 0 | N9: 0 | O9: 0 | P9: 0 | Q9: =SUM(K9:P9) -> 0 | R9: 0 | S9: 0 | T9: 0 | U9: 0 | V9: 0 | W9: =S9*15+T9*6+U9*8 -> 0 | X9: 0 | Y9: 0 | Z9: 0 | AA9: 0 | AB9: 0 | AC9: =Y9*15+Z9*6+AA9*8 -> 0 | AD9: 0
A10: 3 | C10: Bandarban | D10: 0 | E10: 0 | F10: 0 | G10: 0 | H10: 0 | I10: 0 | J10: =SUM(D10:I10) -> 0 | K10: 0 | L10: 0 | M10: 0 | N10: 0 | O10: 0 | P10: 0 | Q10: =SUM(K10:P10) -> 0 | R10: 0 | S10: 0 | T10: 0 | U10: 0 | V10: 0 | W10: =S10*15+T10*6+U10*8 -> 0 | X10: 0 | Y10: 0 | Z10: 0 | AA10: 0 | AB10: 0 | AC10: =Y10*15+Z10*6+AA10*8 -> 0 | AD10: 0
A11: 4 | C11: Rajasthali | D11: 0 | E11: 0 | F11: 0 | G11: 0 | H11: 0 | I11: 0 | J11: =SUM(D11:I11) -> 0 | K11: 0 | L11: 0 | M11: 0 | N11: 0 | O11: 0 | P11: 0 | Q11: =SUM(K11:P11) -> 0 | R11: 0 | S11: 0 | T11: 0 | U11: 0 | V11: 0 | W11: =S11*15+T11*6+U11*8 -> 0 | X11: 0 | Y11: 0 | Z11: 0 | AA11: 0 | AB11: 0 | AC11: =Y11*15+Z11*6+AA11*8 -> 0 | AD11: 0
A12: 5 | C12: Dohazari | D12: 0 | E12: 0 | F12: 0 | G12: 0 | H12: 0 | I12: 0 | J12: =SUM(D12:I12) -> 0 | K12: 0 | L12: 0 | M12: 0 | N12: 0 | O12: 0 | P12: 0 | Q12: =SUM(K12:P12) -> 0 | R12: 0 | S12: 0 | T12: 0 | U12: 0 | V12: 0 | W12: =S12*15+T12*6+U12*8 -> 0 | X12: 0 | Y12: 0 | Z12: 0 | AA12: 0 | AB12: 0 | AC12: =Y12*15+Z12*6+AA12*8 -> 0 | AD12: 0
A13: Satkania Region Total | D13: =SUM(D8:D12) -> 0 | E13: =SUM(E8:E12) -> 0 | F13: =SUM(F8:F12) -> 0 | G13: =SUM(G8:G12) -> 0 | H13: =SUM(H8:H12) -> 0 | I13: =SUM(I8:I12) -> 0 | J13: =SUM(J8:J12) -> 0 | K13: =SUM(K8:K12) -> 0 | ... AD13: =SUM(AD8:AD12) -> 0

Sheet 9
A1: ='1'!A1 -> Afaz Tobacco Company .
A2: ='1'!A2 -> Marketing Department
A3: Month:October-2026
A4: ='1'!A4 -> Daily Sales & Closing Stock Information.
B5: Date:09.10.2026 | G5: Division: Ctg South | U5: Wing: Chittagong
A6: SL. NO | B6: Name of Region | C6: Name of Territory | D6: Brand wise Sales (BITCL) | J6: TOTAL SALES | K6: Brand Wise Closing Stock (BITCL) | Q6: TOTAL Stock | R6: Brand wise Sales (BITCL) | W6: Total Zarda Sales Value | X6: Brand Wise Closing Stock (BITCL) | AC6: Total Zarda C.Stock Value | AD6: Express Empty Packet | AE6: Remark
D7: Wilson | E7: Shahara | F7: Express | G7: Nexus | H7: SB | I7: SM | K7: Wilson | L7: Shahara | M7: Express | N7: Nexus | O7: SB | P7: SM | R7: SLB | S7: 22/25 | T7: 99/14 | U7: 33/15 | X7: SLB | Y7: 22/25 | Z7: 99/14 | AA7: 33/15
A8: 1 | B8: Satkania | C8: Kerani hat | D8: 0 | E8: 0 | F8: 0 | G8: 0 | H8: 0 | I8: 0 | J8: =SUM(D8:I8) -> 0 | K8: 0 | L8: 0 | M8: 0 | N8: 0 | O8: 0 | P8: 0 | Q8: =SUM(K8:P8) -> 0 | R8: 0 | S8: 0 | T8: 0 | U8: 0 | V8: 0 | W8: =S8*15+T8*6+U8*8 -> 0 | X8: 0 | Y8: 0 | Z8: 0 | AA8: 0 | AB8: 0 | AC8: =Y8*15+Z8*6+AA8*8 -> 0 | AD8: 0
A9: 2 | C9: Satkania | D9: 0 | E9: 0 | F9: 0 | G9: 0 | H9: 0 | I9: 0 | J9: =SUM(D9:I9) -> 0 | K9: 0 | L9: 0 | M9: 0 | N9: 0 | O9: 0 | P9: 0 | Q9: =SUM(K9:P9) -> 0 | R9: 0 | S9: 0 | T9: 0 | U9: 0 | V9: 0 | W9: =S9*15+T9*6+U9*8 -> 0 | X9: 0 | Y9: 0 | Z9: 0 | AA9: 0 | AB9: 0 | AC9: =Y9*15+Z9*6+AA9*8 -> 0 | AD9: 0
A10: 3 | C10: Bandarban | D10: 0 | E10: 0 | F10: 0 | G10: 0 | H10: 0 | I10: 0 | J10: =SUM(D10:I10) -> 0 | K10: 0 | L10: 0 | M10: 0 | N10: 0 | O10: 0 | P10: 0 | Q10: =SUM(K10:P10) -> 0 | R10: 0 | S10: 0 | T10: 0 | U10: 0 | V10: 0 | W10: =S10*15+T10*6+U10*8 -> 0 | X10: 0 | Y10: 0 | Z10: 0 | AA10: 0 | AB10: 0 | AC10: =Y10*15+Z10*6+AA10*8 -> 0 | AD10: 0
A11: 4 | C11: Rajasthali | D11: 0 | E11: 0 | F11: 0 | G11: 0 | H11: 0 | I11: 0 | J11: =SUM(D11:I11) -> 0 | K11: 0 | L11: 0 | M11: 0 | N11: 0 | O11: 0 | P11: 0 | Q11: =SUM(K11:P11) -> 0 | R11: 0 | S11: 0 | T11: 0 | U11: 0 | V11: 0 | W11: =S11*15+T11*6+U11*8 -> 0 | X11: 0 | Y11: 0 | Z11: 0 | AA11: 0 | AB11: 0 | AC11: =Y11*15+Z11*6+AA11*8 -> 0 | AD11: 0
A12: 5 | C12: Dohazari | D12: 0 | E12: 0 | F12: 0 | G12: 0 | H12: 0 | I12: 0 | J12: =SUM(D12:I12) -> 0 | K12: 0 | L12: 0 | M12: 0 | N12: 0 | O12: 0 | P12: 0 | Q12: =SUM(K12:P12) -> 0 | R12: 0 | S12: 0 | T12: 0 | U12: 0 | V12: 0 | W12: =S12*15+T12*6+U12*8 -> 0 | X12: 0 | Y12: 0 | Z12: 0 | AA12: 0 | AB12: 0 | AC12: =Y12*15+Z12*6+AA12*8 -> 0 | AD12: 0
A13: Satkania Region Total | D13: =SUM(D8:D12) -> 0 | E13: =SUM(E8:E12) -> 0 | F13: =SUM(F8:F12) -> 0 | G13: =SUM(G8:G12) -> 0 | H13: =SUM(H8:H12) -> 0 | I13: =SUM(I8:I12) -> 0 | J13: =SUM(J8:J12) -> 0 | K13: =SUM(K8:K12) -> 0 | ... AD13: =SUM(AD8:AD12) -> 0

Sheet 10
A1: ='1'!A1 -> Afaz Tobacco Company .
A2: ='1'!A2 -> Marketing Department
A3: Month:October-2026
A4: ='1'!A4 -> Daily Sales & Closing Stock Information.
B5: Date:10.10.2026 | G5: Division: Ctg South | U5: Wing: Chittagong
A6: SL. NO | B6: Name of Region | C6: Name of Territory | D6: Brand wise Sales (BITCL) | J6: TOTAL SALES | K6: Brand Wise Closing Stock (BITCL) | Q6: TOTAL Stock | R6: Brand wise Sales (BITCL) | W6: Total Zarda Sales Value | X6: Brand Wise Closing Stock (BITCL) | AC6: Total Zarda C.Stock Value | AD6: Express Empty Packet | AE6: Remark
D7: Wilson | E7: Shahara | F7: Express | G7: Nexus | H7: SB | I7: SM | K7: Wilson | L7: Shahara | M7: Express | N7: Nexus | O7: SB | P7: SM | R7: SLB | S7: 22/25 | T7: 99/14 | U7: 33/15 | X7: SLB | Y7: 22/25 | Z7: 99/14 | AA7: 33/15
A8: 1 | B8: Satkania | C8: Kerani hat | D8: 0 | E8: 0 | F8: 0 | G8: 0 | H8: 0 | I8: 0 | J8: =SUM(D8:I8) -> 0 | K8: 0 | L8: 0 | M8: 0 | N8: 0 | O8: 0 | P8: 0 | Q8: =SUM(K8:P8) -> 0 | R8: 0 | S8: 0 | T8: 0 | U8: 0 | V8: 0 | W8: =S8*15+T8*6+U8*8 -> 0 | X8: 0 | Y8: 0 | Z8: 0 | AA8: 0 | AB8: 0 | AC8: =Y8*15+Z8*6+AA8*8 -> 0 | AD8: 0
A9: 2 | C9: Satkania | D9: 0 | E9: 0 | F9: 0 | G9: 0 | H9: 0 | I9: 0 | J9: =SUM(D9:I9) -> 0 | K9: 0 | L9: 0 | M9: 0 | N9: 0 | O9: 0 | P9: 0 | Q9: =SUM(K9:P9) -> 0 | R9: 0 | S9: 0 | T9: 0 | U9: 0 | V9: 0 | W9: =S9*15+T9*6+U9*8 -> 0 | X9: 0 | Y9: 0 | Z9: 0 | AA9: 0 | AB9: 0 | AC9: =Y9*15+Z9*6+AA9*8 -> 0 | AD9: 0
A10: 3 | C10: Bandarban | D10: 0 | E10: 0 | F10: 0 | G10: 0 | H10: 0 | I10: 0 | J10: =SUM(D10:I10) -> 0 | K10: 0 | L10: 0 | M10: 0 | N10: 0 | O10: 0 | P10: 0 | Q10: =SUM(K10:P10) -> 0 | R10: 0 | S10: 0 | T10: 0 | U10: 0 | V10: 0 | W10: =S10*15+T10*6+U10*8 -> 0 | X10: 0 | Y10: 0 | Z10: 0 | AA10: 0 | AB10: 0 | AC10: =Y10*15+Z10*6+AA10*8 -> 0 | AD10: 0
A11: 4 | C11: Rajasthali | D11: 0 | E11: 0 | F11: 0 | G11: 0 | H11: 0 | I11: 0 | J11: =SUM(D11:I11) -> 0 | K11: 0 | L11: 0 | M11: 0 | N11: 0 | O11: 0 | P11: 0 | Q11: =SUM(K11:P11) -> 0 | R11: 0 | S11: 0 | T11: 0 | U11: 0 | V11: 0 | W11: =S11*15+T11*6+U11*8 -> 0 | X11: 0 | Y11: 0 | Z11: 0 | AA11: 0 | AB11: 0 | AC11: =Y11*15+Z11*6+AA11*8 -> 0 | AD11: 0
A12: 5 | C12: Dohazari | D12: 0 | E12: 0 | F12: 0 | G12: 0 | H12: 0 | I12: 0 | J12: =SUM(D12:I12) -> 0 | K12: 0 | L12: 0 | M12: 0 | N12: 0 | O12: 0 | P12: 0 | Q12: =SUM(K12:P12) -> 0 | R12: 0 | S12: 0 | T12: 0 | U12: 0 | V12: 0 | W12: =S12*15+T12*6+U12*8 -> 0 | X12: 0 | Y12: 0 | Z12: 0 | AA12: 0 | AB12: 0 | AC12: =Y12*15+Z12*6+AA12*8 -> 0 | AD12: 0
A13: Satkania Region Total | D13: =SUM(D8:D12) -> 0 | E13: =SUM(E8:E12) -> 0 | F13: =SUM(F8:F12) -> 0 | G13: =SUM(G8:G12) -> 0 | H13: =SUM(H8:H12) -> 0 | I13: =SUM(I8:I12) -> 0 | J13: =SUM(J8:J12) -> 0 | K13: =SUM(K8:K12) -> 0 | ... AD13: =SUM(AD8:AD12) -> 0

Sheet 11
A1: ='1'!A1 -> Afaz Tobacco Company .
A2: ='1'!A2 -> Marketing Department
A3: Month:October-2026
A4: ='1'!A4 -> Daily Sales & Closing Stock Information.
B5: Date:11.10.2026 | G5: Division: Ctg South | U5: Wing: Chittagong
A6: SL. NO | B6: Name of Region | C6: Name of Territory | D6: Brand wise Sales (BITCL) | J6: TOTAL SALES | K6: Brand Wise Closing Stock (BITCL) | Q6: TOTAL Stock | R6: Brand wise Sales (BITCL) | W6: Total Zarda Sales Value | X6: Brand Wise Closing Stock (BITCL) | AC6: Total Zarda C.Stock Value | AD6: Express Empty Packet | AE6: Remark
D7: Wilson | E7: Shahara | F7: Express | G7: Nexus | H7: SB | I7: SM | K7: Wilson | L7: Shahara | M7: Express | N7: Nexus | O7: SB | P7: SM | R7: SLB | S7: 22/25 | T7: 99/14 | U7: 33/15 | X7: SLB | Y7: 22/25 | Z7: 99/14 | AA7: 33/15
A8: 1 | B8: Satkania | C8: Kerani hat | D8: 0 | E8: 0 | F8: 0 | G8: 0 | H8: 0 | I8: 0 | J8: =SUM(D8:I8) -> 0 | K8: 0 | L8: 0 | M8: 0 | N8: 0 | O8: 0 | P8: 0 | Q8: =SUM(K8:P8) -> 0 | R8: 0 | S8: 0 | T8: 0 | U8: 0 | V8: 0 | W8: =S8*15+T8*6+U8*8 -> 0 | X8: 0 | Y8: 0 | Z8: 0 | AA8: 0 | AB8: 0 | AC8: =Y8*15+Z8*6+AA8*8 -> 0 | AD8: 0
A9: 2 | C9: Satkania | D9: 0 | E9: 0 | F9: 0 | G9: 0 | H9: 0 | I9: 0 | J9: =SUM(D9:I9) -> 0 | K9: 0 | L9: 0 | M9: 0 | N9: 0 | O9: 0 | P9: 0 | Q9: =SUM(K9:P9) -> 0 | R9: 0 | S9: 0 | T9: 0 | U9: 0 | V9: 0 | W9: =S9*15+T9*6+U9*8 -> 0 | X9: 0 | Y9: 0 | Z9: 0 | AA9: 0 | AB9: 0 | AC9: =Y9*15+Z9*6+AA9*8 -> 0 | AD9: 0
A10: 3 | C10: Bandarban | D10: 0 | E10: 0 | F10: 0 | G10: 0 | H10: 0 | I10: 0 | J10: =SUM(D10:I10) -> 0 | K10: 0 | L10: 0 | M10: 0 | N10: 0 | O10: 0 | P10: 0 | Q10: =SUM(K10:P10) -> 0 | R10: 0 | S10: 0 | T10: 0 | U10: 0 | V10: 0 | W10: =S10*15+T10*6+U10*8 -> 0 | X10: 0 | Y10: 0 | Z10: 0 | AA10: 0 | AB10: 0 | AC10: =Y10*15+Z10*6+AA10*8 -> 0 | AD10: 0
A11: 4 | C11: Rajasthali | D11: 0 | E11: 0 | F11: 0 | G11: 0 | H11: 0 | I11: 0 | J11: =SUM(D11:I11) -> 0 | K11: 0 | L11: 0 | M11: 0 | N11: 0 | O11: 0 | P11: 0 | Q11: =SUM(K11:P11) -> 0 | R11: 0 | S11: 0 | T11: 0 | U11: 0 | V11: 0 | W11: =S11*15+T11*6+U11*8 -> 0 | X11: 0 | Y11: 0 | Z11: 0 | AA11: 0 | AB11: 0 | AC11: =Y11*15+Z11*6+AA11*8 -> 0 | AD11: 0
A12: 5 | C12: Dohazari | D12: 0 | E12: 0 | F12: 0 | G12: 0 | H12: 0 | I12: 0 | J12: =SUM(D12:I12) -> 0 | K12: 0 | L12: 0 | M12: 0 | N12: 0 | O12: 0 | P12: 0 | Q12: =SUM(K12:P12) -> 0 | R12: 0 | S12: 0 | T12: 0 | U12: 0 | V12: 0 | W12: =S12*15+T12*6+U12*8 -> 0 | X12: 0 | Y12: 0 | Z12: 0 | AA12: 0 | AB12: 0 | AC12: =Y12*15+Z12*6+AA12*8 -> 0 | AD12: 0
A13: Satkania Region Total | D13: =SUM(D8:D12) -> 0 | E13: =SUM(E8:E12) -> 0 | F13: =SUM(F8:F12) -> 0 | G13: =SUM(G8:G12) -> 0 | H13: =SUM(H8:H12) -> 0 | I13: =SUM(I8:I12) -> 0 | J13: =SUM(J8:J12) -> 0 | K13: =SUM(K8:K12) -> 0 | ... AD13: =SUM(AD8:AD12) -> 0

Sheet 12
A1: ='1'!A1 -> Afaz Tobacco Company .
A2: ='1'!A2 -> Marketing Department
A3: Month:October-2026
A4: ='1'!A4 -> Daily Sales & Closing Stock Information.
B5: Date:12.10.2026 | G5: Division: Ctg South | U5: Wing: Chittagong
A6: SL. NO | B6: Name of Region | C6: Name of Territory | D6: Brand wise Sales (BITCL) | J6: TOTAL SALES | K6: Brand Wise Closing Stock (BITCL) | Q6: TOTAL Stock | R6: Brand wise Sales (BITCL) | W6: Total Zarda Sales Value | X6: Brand Wise Closing Stock (BITCL) | AC6: Total Zarda C.Stock Value | AD6: Express Empty Packet | AE6: Remark
D7: Wilson | E7: Shahara | F7: Express | G7: Nexus | H7: SB | I7: SM | K7: Wilson | L7: Shahara | M7: Express | N7: Nexus | O7: SB | P7: SM | R7: SLB | S7: 22/25 | T7: 99/14 | U7: 33/15 | X7: SLB | Y7: 22/25 | Z7: 99/14 | AA7: 33/15
A8: 1 | B8: Satkania | C8: Kerani hat | D8: 0 | E8: 0 | F8: 0 | G8: 0 | H8: 0 | I8: 0 | J8: =SUM(D8:I8) -> 0 | K8: 0 | L8: 0 | M8: 0 | N8: 0 | O8: 0 | P8: 0 | Q8: =SUM(K8:P8) -> 0 | R8: 0 | S8: 0 | T8: 0 | U8: 0 | V8: 0 | W8: =S8*15+T8*6+U8*8 -> 0 | X8: 0 | Y8: 0 | Z8: 0 | AA8: 0 | AB8: 0 | AC8: =Y8*15+Z8*6+AA8*8 -> 0 | AD8: 0
A9: 2 | C9: Satkania | D9: 0 | E9: 0 | F9: 0 | G9: 0 | H9: 0 | I9: 0 | J9: =SUM(D9:I9) -> 0 | K9: 0 | L9: 0 | M9: 0 | N9: 0 | O9: 0 | P9: 0 | Q9: =SUM(K9:P9) -> 0 | R9: 0 | S9: 0 | T9: 0 | U9: 0 | V9: 0 | W9: =S9*15+T9*6+U9*8 -> 0 | X9: 0 | Y9: 0 | Z9: 0 | AA9: 0 | AB9: 0 | AC9: =Y9*15+Z9*6+AA9*8 -> 0 | AD9: 0
A10: 3 | C10: Bandarban | D10: 0 | E10: 0 | F10: 0 | G10: 0 | H10: 0 | I10: 0 | J10: =SUM(D10:I10) -> 0 | K10: 0 | L10: 0 | M10: 0 | N10: 0 | O10: 0 | P10: 0 | Q10: =SUM(K10:P10) -> 0 | R10: 0 | S10: 0 | T10: 0 | U10: 0 | V10: 0 | W10: =S10*15+T10*6+U10*8 -> 0 | X10: 0 | Y10: 0 | Z10: 0 | AA10: 0 | AB10: 0 | AC10: =Y10*15+Z10*6+AA10*8 -> 0 | AD10: 0
A11: 4 | C11: Rajasthali | D11: 0 | E11: 0 | F11: 0 | G11: 0 | H11: 0 | I11: 0 | J11: =SUM(D11:I11) -> 0 | K11: 0 | L11: 0 | M11: 0 | N11: 0 | O11: 0 | P11: 0 | Q11: =SUM(K11:P11) -> 0 | R11: 0 | S11: 0 | T11: 0 | U11: 0 | V11: 0 | W11: =S11*15+T11*6+U11*8 -> 0 | X11: 0 | Y11: 0 | Z11: 0 | AA11: 0 | AB11: 0 | AC11: =Y11*15+Z11*6+AA11*8 -> 0 | AD11: 0
A12: 5 | C12: Dohazari | D12: 0 | E12: 0 | F12: 0 | G12: 0 | H12: 0 | I12: 0 | J12: =SUM(D12:I12) -> 0 | K12: 0 | L12: 0 | M12: 0 | N12: 0 | O12: 0 | P12: 0 | Q12: =SUM(K12:P12) -> 0 | R12: 0 | S12: 0 | T12: 0 | U12: 0 | V12: 0 | W12: =S12*15+T12*6+U12*8 -> 0 | X12: 0 | Y12: 0 | Z12: 0 | AA12: 0 | AB12: 0 | AC12: =Y12*15+Z12*6+AA12*8 -> 0 | AD12: 0
A13: Satkania Region Total | D13: =SUM(D8:D12) -> 0 | E13: =SUM(E8:E12) -> 0 | F13: =SUM(F8:F12) -> 0 | G13: =SUM(G8:G12) -> 0 | H13: =SUM(H8:H12) -> 0 | I13: =SUM(I8:I12) -> 0 | J13: =SUM(J8:J12) -> 0 | K13: =SUM(K8:K12) -> 0 | ... AD13: =SUM(AD8:AD12) -> 0

Sheet 13
A1: ='1'!A1 -> Afaz Tobacco Company .
A2: ='1'!A2 -> Marketing Department
A3: Month:October-2026
A4: ='1'!A4 -> Daily Sales & Closing Stock Information.
B5: Date:13.10.2026 | G5: Division: Ctg South | U5: Wing: Chittagong
A6: SL. NO | B6: Name of Region | C6: Name of Territory | D6: Brand wise Sales (BITCL) | J6: TOTAL SALES | K6: Brand Wise Closing Stock (BITCL) | Q6: TOTAL Stock | R6: Brand wise Sales (BITCL) | W6: Total Zarda Sales Value | X6: Brand Wise Closing Stock (BITCL) | AC6: Total Zarda C.Stock Value | AD6: Express Empty Packet | AE6: Remark
D7: Wilson | E7: Shahara | F7: Express | G7: Nexus | H7: SB | I7: SM | K7: Wilson | L7: Shahara | M7: Express | N7: Nexus | O7: SB | P7: SM | R7: SLB | S7: 22/25 | T7: 99/14 | U7: 33/15 | X7: SLB | Y7: 22/25 | Z7: 99/14 | AA7: 33/15
A8: 1 | B8: Satkania | C8: Kerani hat | D8: 0 | E8: 0 | F8: 0 | G8: 0 | H8: 0 | I8: 0 | J8: =SUM(D8:I8) -> 0 | K8: 0 | L8: 0 | M8: 0 | N8: 0 | O8: 0 | P8: 0 | Q8: =SUM(K8:P8) -> 0 | R8: 0 | S8: 0 | T8: 0 | U8: 0 | V8: 0 | W8: =S8*15+T8*6+U8*8 -> 0 | X8: 0 | Y8: 0 | Z8: 0 | AA8: 0 | AB8: 0 | AC8: =Y8*15+Z8*6+AA8*8 -> 0 | AD8: 0
A9: 2 | C9: Satkania | D9: 0 | E9: 0 | F9: 0 | G9: 0 | H9: 0 | I9: 0 | J9: =SUM(D9:I9) -> 0 | K9: 0 | L9: 0 | M9: 0 | N9: 0 | O9: 0 | P9: 0 | Q9: =SUM(K9:P9) -> 0 | R9: 0 | S9: 0 | T9: 0 | U9: 0 | V9: 0 | W9: =S9*15+T9*6+U9*8 -> 0 | X9: 0 | Y9: 0 | Z9: 0 | AA9: 0 | AB9: 0 | AC9: =Y9*15+Z9*6+AA9*8 -> 0 | AD9: 0
A10: 3 | C10: Bandarban | D10: 0 | E10: 0 | F10: 0 | G10: 0 | H10: 0 | I10: 0 | J10: =SUM(D10:I10) -> 0 | K10: 0 | L10: 0 | M10: 0 | N10: 0 | O10: 0 | P10: 0 | Q10: =SUM(K10:P10) -> 0 | R10: 0 | S10: 0 | T10: 0 | U10: 0 | V10: 0 | W10: =S10*15+T10*6+U10*8 -> 0 | X10: 0 | Y10: 0 | Z10: 0 | AA10: 0 | AB10: 0 | AC10: =Y10*15+Z10*6+AA10*8 -> 0 | AD10: 0
A11: 4 | C11: Rajasthali | D11: 0 | E11: 0 | F11: 0 | G11: 0 | H11: 0 | I11: 0 | J11: =SUM(D11:I11) -> 0 | K11: 0 | L11: 0 | M11: 0 | N11: 0 | O11: 0 | P11: 0 | Q11: =SUM(K11:P11) -> 0 | R11: 0 | S11: 0 | T11: 0 | U11: 0 | V11: 0 | W11: =S11*15+T11*6+U11*8 -> 0 | X11: 0 | Y11: 0 | Z11: 0 | AA11: 0 | AB11: 0 | AC11: =Y11*15+Z11*6+AA11*8 -> 0 | AD11: 0
A12: 5 | C12: Dohazari | D12: 0 | E12: 0 | F12: 0 | G12: 0 | H12: 0 | I12: 0 | J12: =SUM(D12:I12) -> 0 | K12: 0 | L12: 0 | M12: 0 | N12: 0 | O12: 0 | P12: 0 | Q12: =SUM(K12:P12) -> 0 | R12: 0 | S12: 0 | T12: 0 | U12: 0 | V12: 0 | W12: =S12*15+T12*6+U12*8 -> 0 | X12: 0 | Y12: 0 | Z12: 0 | AA12: 0 | AB12: 0 | AC12: =Y12*15+Z12*6+AA12*8 -> 0 | AD12: 0
A13: Satkania Region Total | D13: =SUM(D8:D12) -> 0 | E13: =SUM(E8:E12) -> 0 | F13: =SUM(F8:F12) -> 0 | G13: =SUM(G8:G12) -> 0 | H13: =SUM(H8:H12) -> 0 | I13: =SUM(I8:I12) -> 0 | J13: =SUM(J8:J12) -> 0 | K13: =SUM(K8:K12) -> 0 | ... AD13: =SUM(AD8:AD12) -> 0

Sheet 14
A1: ='1'!A1 -> Afaz Tobacco Company .
A2: ='1'!A2 -> Marketing Department
A3: Month:October-2026
A4: ='1'!A4 -> Daily Sales & Closing Stock Information.
B5: Date:14.10.2026 | G5: Division: Ctg South | U5: Wing: Chittagong
A6: SL. NO | B6: Name of Region | C6: Name of Territory | D6: Brand wise Sales (BITCL) | J6: TOTAL SALES | K6: Brand Wise Closing Stock (BITCL) | Q6: TOTAL Stock | R6: Brand wise Sales (BITCL) | W6: Total Zarda Sales Value | X6: Brand Wise Closing Stock (BITCL) | AC6: Total Zarda C.Stock Value | AD6: Express Empty Packet | AE6: Remark
D7: Wilson | E7: Shahara | F7: Express | G7: Nexus | H7: SB | I7: SM | K7: Wilson | L7: Shahara | M7: Express | N7: Nexus | O7: SB | P7: SM | R7: SLB | S7: 22/25 | T7: 99/14 | U7: 33/15 | X7: SLB | Y7: 22/25 | Z7: 99/14 | AA7: 33/15
A8: 1 | B8: Satkania | C8: Kerani hat | D8: 0 | E8: 0 | F8: 0 | G8: 0 | H8: 0 | I8: 0 | J8: =SUM(D8:I8) -> 0 | K8: 0 | L8: 0 | M8: 0 | N8: 0 | O8: 0 | P8: 0 | Q8: =SUM(K8:P8) -> 0 | R8: 0 | S8: 0 | T8: 0 | U8: 0 | V8: 0 | W8: =S8*15+T8*6+U8*8 -> 0 | X8: 0 | Y8: 0 | Z8: 0 | AA8: 0 | AB8: 0 | AC8: =Y8*15+Z8*6+AA8*8 -> 0 | AD8: 0
A9: 2 | C9: Satkania | D9: 0 | E9: 0 | F9: 0 | G9: 0 | H9: 0 | I9: 0 | J9: =SUM(D9:I9) -> 0 | K9: 0 | L9: 0 | M9: 0 | N9: 0 | O9: 0 | P9: 0 | Q9: =SUM(K9:P9) -> 0 | R9: 0 | S9: 0 | T9: 0 | U9: 0 | V9: 0 | W9: =S9*15+T9*6+U9*8 -> 0 | X9: 0 | Y9: 0 | Z9: 0 | AA9: 0 | AB9: 0 | AC9: =Y9*15+Z9*6+AA9*8 -> 0 | AD9: 0
A10: 3 | C10: Bandarban | D10: 0 | E10: 0 | F10: 0 | G10: 0 | H10: 0 | I10: 0 | J10: =SUM(D10:I10) -> 0 | K10: 0 | L10: 0 | M10: 0 | N10: 0 | O10: 0 | P10: 0 | Q10: =SUM(K10:P10) -> 0 | R10: 0 | S10: 0 | T10: 0 | U10: 0 | V10: 0 | W10: =S10*15+T10*6+U10*8 -> 0 | X10: 0 | Y10: 0 | Z10: 0 | AA10: 0 | AB10: 0 | AC10: =Y10*15+Z10*6+AA10*8 -> 0 | AD10: 0
A11: 4 | C11: Rajasthali | D11: 0 | E11: 0 | F11: 0 | G11: 0 | H11: 0 | I11: 0 | J11: =SUM(D11:I11) -> 0 | K11: 0 | L11: 0 | M11: 0 | N11: 0 | O11: 0 | P11: 0 | Q11: =SUM(K11:P11) -> 0 | R11: 0 | S11: 0 | T11: 0 | U11: 0 | V11: 0 | W11: =S11*15+T11*6+U11*8 -> 0 | X11: 0 | Y11: 0 | Z11: 0 | AA11: 0 | AB11: 0 | AC11: =Y11*15+Z11*6+AA11*8 -> 0 | AD11: 0
A12: 5 | C12: Dohazari | D12: 0 | E12: 0 | F12: 0 | G12: 0 | H12: 0 | I12: 0 | J12: =SUM(D12:I12) -> 0 | K12: 0 | L12: 0 | M12: 0 | N12: 0 | O12: 0 | P12: 0 | Q12: =SUM(K12:P12) -> 0 | R12: 0 | S12: 0 | T12: 0 | U12: 0 | V12: 0 | W12: =S12*15+T12*6+U12*8 -> 0 | X12: 0 | Y12: 0 | Z12: 0 | AA12: 0 | AB12: 0 | AC12: =Y12*15+Z12*6+AA12*8 -> 0 | AD12: 0
A13: Satkania Region Total | D13: =SUM(D8:D12) -> 0 | E13: =SUM(E8:E12) -> 0 | F13: =SUM(F8:F12) -> 0 | G13: =SUM(G8:G12) -> 0 | H13: =SUM(H8:H12) -> 0 | I13: =SUM(I8:I12) -> 0 | J13: =SUM(J8:J12) -> 0 | K13: =SUM(K8:K12) -> 0 | ... AD13: =SUM(AD8:AD12) -> 0

Sheet 15
A1: ='1'!A1 -> Afaz Tobacco Company .
A2: ='1'!A2 -> Marketing Department
A3: Month:October-2026
A4: ='1'!A4 -> Daily Sales & Closing Stock Information.
B5: Date:15.10.2026 | G5: Division: Ctg South | U5: Wing: Chittagong
A6: SL. NO | B6: Name of Region | C6: Name of Territory | D6: Brand wise Sales (BITCL) | J6: TOTAL SALES | K6: Brand Wise Closing Stock (BITCL) | Q6: TOTAL Stock | R6: Brand wise Sales (BITCL) | W6: Total Zarda Sales Value | X6: Brand Wise Closing Stock (BITCL) | AC6: Total Zarda C.Stock Value | AD6: Express Empty Packet | AE6: Remark
D7: Wilson | E7: Shahara | F7: Express | G7: Nexus | H7: SB | I7: SM | K7: Wilson | L7: Shahara | M7: Express | N7: Nexus | O7: SB | P7: SM | R7: SLB | S7: 22/25 | T7: 99/14 | U7: 33/15 | X7: SLB | Y7: 22/25 | Z7: 99/14 | AA7: 33/15
A8: 1 | B8: Satkania | C8: Kerani hat | D8: 0 | E8: 0 | F8: 0 | G8: 0 | H8: 0 | I8: 0 | J8: =SUM(D8:I8) -> 0 | K8: 0 | L8: 0 | M8: 0 | N8: 0 | O8: 0 | P8: 0 | Q8: =SUM(K8:P8) -> 0 | R8: 0 | S8: 0 | T8: 0 | U8: 0 | V8: 0 | W8: =S8*15+T8*6+U8*8 -> 0 | X8: 0 | Y8: 0 | Z8: 0 | AA8: 0 | AB8: 0 | AC8: =Y8*15+Z8*6+AA8*8 -> 0 | AD8: 0
A9: 2 | C9: Satkania | D9: 0 | E9: 0 | F9: 0 | G9: 0 | H9: 0 | I9: 0 | J9: =SUM(D9:I9) -> 0 | K9: 0 | L9: 0 | M9: 0 | N9: 0 | O9: 0 | P9: 0 | Q9: =SUM(K9:P9) -> 0 | R9: 0 | S9: 0 | T9: 0 | U9: 0 | V9: 0 | W9: =S9*15+T9*6+U9*8 -> 0 | X9: 0 | Y9: 0 | Z9: 0 | AA9: 0 | AB9: 0 | AC9: =Y9*15+Z9*6+AA9*8 -> 0 | AD9: 0
A10: 3 | C10: Bandarban | D10: 0 | E10: 0 | F10: 0 | G10: 0 | H10: 0 | I10: 0 | J10: =SUM(D10:I10) -> 0 | K10: 0 | L10: 0 | M10: 0 | N10: 0 | O10: 0 | P10: 0 | Q10: =SUM(K10:P10) -> 0 | R10: 0 | S10: 0 | T10: 0 | U10: 0 | V10: 0 | W10: =S10*15+T10*6+U10*8 -> 0 | X10: 0 | Y10: 0 | Z10: 0 | AA10: 0 | AB10: 0 | AC10: =Y10*15+Z10*6+AA10*8 -> 0 | AD10: 0
A11: 4 | C11: Rajasthali | D11: 0 | E11: 0 | F11: 0 | G11: 0 | H11: 0 | I11: 0 | J11: =SUM(D11:I11) -> 0 | K11: 0 | L11: 0 | M11: 0 | N11: 0 | O11: 0 | P11: 0 | Q11: =SUM(K11:P11) -> 0 | R11: 0 | S11: 0 | T11: 0 | U11: 0 | V11: 0 | W11: =S11*15+T11*6+U11*8 -> 0 | X11: 0 | Y11: 0 | Z11: 0 | AA11: 0 | AB11: 0 | AC11: =Y11*15+Z11*6+AA11*8 -> 0 | AD11: 0
A12: 5 | C12: Dohazari | D12: 0 | E12: 0 | F12: 0 | G12: 0 | H12: 0 | I12: 0 | J12: =SUM(D12:I12) -> 0 | K12: 0 | L12: 0 | M12: 0 | N12: 0 | O12: 0 | P12: 0 | Q12: =SUM(K12:P12) -> 0 | R12: 0 | S12: 0 | T12: 0 | U12: 0 | V12: 0 | W12: =S12*15+T12*6+U12*8 -> 0 | X12: 0 | Y12: 0 | Z12: 0 | AA12: 0 | AB12: 0 | AC12: =Y12*15+Z12*6+AA12*8 -> 0 | AD12: 0
A13: Satkania Region Total | D13: =SUM(D8:D12) -> 0 | E13: =SUM(E8:E12) -> 0 | F13: =SUM(F8:F12) -> 0 | G13: =SUM(G8:G12) -> 0 | H13: =SUM(H8:H12) -> 0 | I13: =SUM(I8:I12) -> 0 | J13: =SUM(J8:J12) -> 0 | K13: =SUM(K8:K12) -> 0 | ... AD13: =SUM(AD8:AD12) -> 0

Sheet 16
A1: ='1'!A1 -> Afaz Tobacco Company .
A2: ='1'!A2 -> Marketing Department
A3: Month:October-2026
A4: ='1'!A4 -> Daily Sales & Closing Stock Information.
B5: Date:16.10.2026 | G5: Division: Ctg South | U5: Wing: Chittagong
A6: SL. NO | B6: Name of Region | C6: Name of Territory | D6: Brand wise Sales (BITCL) | J6: TOTAL SALES | K6: Brand Wise Closing Stock (BITCL) | Q6: TOTAL Stock | R6: Brand wise Sales (BITCL) | W6: Total Zarda Sales Value | X6: Brand Wise Closing Stock (BITCL) | AC6: Total Zarda C.Stock Value | AD6: Express Empty Packet | AE6: Remark
D7: Wilson | E7: Shahara | F7: Express | G7: Nexus | H7: SB | I7: SM | K7: Wilson | L7: Shahara | M7: Express | N7: Nexus | O7: SB | P7: SM | R7: SLB | S7: 22/25 | T7: 99/14 | U7: 33/15 | X7: SLB | Y7: 22/25 | Z7: 99/14 | AA7: 33/15
A8: 1 | B8: Satkania | C8: Kerani hat | D8: 0 | E8: 0 | F8: 0 | G8: 0 | H8: 0 | I8: 0 | J8: =SUM(D8:I8) -> 0 | K8: 0 | L8: 0 | M8: 0 | N8: 0 | O8: 0 | P8: 0 | Q8: =SUM(K8:P8) -> 0 | R8: 0 | S8: 0 | T8: 0 | U8: 0 | V8: 0 | W8: =S8*15+T8*6+U8*8 -> 0 | X8: 0 | Y8: 0 | Z8: 0 | AA8: 0 | AB8: 0 | AC8: =Y8*15+Z8*6+AA8*8 -> 0 | AD8: 0
A9: 2 | C9: Satkania | D9: 0 | E9: 0 | F9: 0 | G9: 0 | H9: 0 | I9: 0 | J9: =SUM(D9:I9) -> 0 | K9: 0 | L9: 0 | M9: 0 | N9: 0 | O9: 0 | P9: 0 | Q9: =SUM(K9:P9) -> 0 | R9: 0 | S9: 0 | T9: 0 | U9: 0 | V9: 0 | W9: =S9*15+T9*6+U9*8 -> 0 | X9: 0 | Y9: 0 | Z9: 0 | AA9: 0 | AB9: 0 | AC9: =Y9*15+Z9*6+AA9*8 -> 0 | AD9: 0
A10: 3 | C10: Bandarban | D10: 0 | E10: 0 | F10: 0 | G10: 0 | H10: 0 | I10: 0 | J10: =SUM(D10:I10) -> 0 | K10: 0 | L10: 0 | M10: 0 | N10: 0 | O10: 0 | P10: 0 | Q10: =SUM(K10:P10) -> 0 | R10: 0 | S10: 0 | T10: 0 | U10: 0 | V10: 0 | W10: =S10*15+T10*6+U10*8 -> 0 | X10: 0 | Y10: 0 | Z10: 0 | AA10: 0 | AB10: 0 | AC10: =Y10*15+Z10*6+AA10*8 -> 0 | AD10: 0
A11: 4 | C11: Rajasthali | D11: 0 | E11: 0 | F11: 0 | G11: 0 | H11: 0 | I11: 0 | J11: =SUM(D11:I11) -> 0 | K11: 0 | L11: 0 | M11: 0 | N11: 0 | O11: 0 | P11: 0 | Q11: =SUM(K11:P11) -> 0 | R11: 0 | S11: 0 | T11: 0 | U11: 0 | V11: 0 | W11: =S11*15+T11*6+U11*8 -> 0 | X11: 0 | Y11: 0 | Z11: 0 | AA11: 0 | AB11: 0 | AC11: =Y11*15+Z11*6+AA11*8 -> 0 | AD11: 0
A12: 5 | C12: Dohazari | D12: 0 | E12: 0 | F12: 0 | G12: 0 | H12: 0 | I12: 0 | J12: =SUM(D12:I12) -> 0 | K12: 0 | L12: 0 | M12: 0 | N12: 0 | O12: 0 | P12: 0 | Q12: =SUM(K12:P12) -> 0 | R12: 0 | S12: 0 | T12: 0 | U12: 0 | V12: 0 | W12: =S12*15+T12*6+U12*8 -> 0 | X12: 0 | Y12: 0 | Z12: 0 | AA12: 0 | AB12: 0 | AC12: =Y12*15+Z12*6+AA12*8 -> 0 | AD12: 0
A13: Satkania Region Total | D13: =SUM(D8:D12) -> 0 | E13: =SUM(E8:E12) -> 0 | F13: =SUM(F8:F12) -> 0 | G13: =SUM(G8:G12) -> 0 | H13: =SUM(H8:H12) -> 0 | I13: =SUM(I8:I12) -> 0 | J13: =SUM(J8:J12) -> 0 | K13: =SUM(K8:K12) -> 0 | ... AD13: =SUM(AD8:AD12) -> 0

Sheet 17
A1: ='1'!A1 -> Afaz Tobacco Company .
A2: ='1'!A2 -> Marketing Department
A3: Month:October-2026
A4: ='1'!A4 -> Daily Sales & Closing Stock Information.
B5: Date:17.10.2026 | G5: Division: Ctg South | U5: Wing: Chittagong
A6: SL. NO | B6: Name of Region | C6: Name of Territory | D6: Brand wise Sales (BITCL) | J6: TOTAL SALES | K6: Brand Wise Closing Stock (BITCL) | Q6: TOTAL Stock | R6: Brand wise Sales (BITCL) | W6: Total Zarda Sales Value | X6: Brand Wise Closing Stock (BITCL) | AC6: Total Zarda C.Stock Value | AD6: Express Empty Packet | AE6: Remark
D7: Wilson | E7: Shahara | F7: Express | G7: Nexus | H7: SB | I7: SM | K7: Wilson | L7: Shahara | M7: Express | N7: Nexus | O7: SB | P7: SM | R7: SLB | S7: 22/25 | T7: 99/14 | U7: 33/15 | X7: SLB | Y7: 22/25 | Z7: 99/14 | AA7: 33/15
A8: 1 | B8: Satkania | C8: Kerani hat | D8: 0 | E8: 0 | F8: 0 | G8: 0 | H8: 0 | I8: 0 | J8: =SUM(D8:I8) -> 0 | K8: 0 | L8: 0 | M8: 0 | N8: 0 | O8: 0 | P8: 0 | Q8: =SUM(K8:P8) -> 0 | R8: 0 | S8: 0 | T8: 0 | U8: 0 | V8: 0 | W8: =S8*15+T8*6+U8*8 -> 0 | X8: 0 | Y8: 0 | Z8: 0 | AA8: 0 | AB8: 0 | AC8: =Y8*15+Z8*6+AA8*8 -> 0 | AD8: 0
A9: 2 | C9: Satkania | D9: 0 | E9: 0 | F9: 0 | G9: 0 | H9: 0 | I9: 0 | J9: =SUM(D9:I9) -> 0 | K9: 0 | L9: 0 | M9: 0 | N9: 0 | O9: 0 | P9: 0 | Q9: =SUM(K9:P9) -> 0 | R9: 0 | S9: 0 | T9: 0 | U9: 0 | V9: 0 | W9: =S9*15+T9*6+U9*8 -> 0 | X9: 0 | Y9: 0 | Z9: 0 | AA9: 0 | AB9: 0 | AC9: =Y9*15+Z9*6+AA9*8 -> 0 | AD9: 0
A10: 3 | C10: Bandarban | D10: 0 | E10: 0 | F10: 0 | G10: 0 | H10: 0 | I10: 0 | J10: =SUM(D10:I10) -> 0 | K10: 0 | L10: 0 | M10: 0 | N10: 0 | O10: 0 | P10: 0 | Q10: =SUM(K10:P10) -> 0 | R10: 0 | S10: 0 | T10: 0 | U10: 0 | V10: 0 | W10: =S10*15+T10*6+U10*8 -> 0 | X10: 0 | Y10: 0 | Z10: 0 | AA10: 0 | AB10: 0 | AC10: =Y10*15+Z10*6+AA10*8 -> 0 | AD10: 0
A11: 4 | C11: Rajasthali | D11: 0 | E11: 0 | F11: 0 | G11: 0 | H11: 0 | I11: 0 | J11: =SUM(D11:I11) -> 0 | K11: 0 | L11: 0 | M11: 0 | N11: 0 | O11: 0 | P11: 0 | Q11: =SUM(K11:P11) -> 0 | R11: 0 | S11: 0 | T11: 0 | U11: 0 | V11: 0 | W11: =S11*15+T11*6+U11*8 -> 0 | X11: 0 | Y11: 0 | Z11: 0 | AA11: 0 | AB11: 0 | AC11: =Y11*15+Z11*6+AA11*8 -> 0 | AD11: 0
A12: 5 | C12: Dohazari | D12: 0 | E12: 0 | F12: 0 | G12: 0 | H12: 0 | I12: 0 | J12: =SUM(D12:I12) -> 0 | K12: 0 | L12: 0 | M12: 0 | N12: 0 | O12: 0 | P12: 0 | Q12: =SUM(K12:P12) -> 0 | R12: 0 | S12: 0 | T12: 0 | U12: 0 | V12: 0 | W12: =S12*15+T12*6+U12*8 -> 0 | X12: 0 | Y12: 0 | Z12: 0 | AA12: 0 | AB12: 0 | AC12: =Y12*15+Z12*6+AA12*8 -> 0 | AD12: 0
A13: Satkania Region Total | D13: =SUM(D8:D12) -> 0 | E13: =SUM(E8:E12) -> 0 | F13: =SUM(F8:F12) -> 0 | G13: =SUM(G8:G12) -> 0 | H13: =SUM(H8:H12) -> 0 | I13: =SUM(I8:I12) -> 0 | J13: =SUM(J8:J12) -> 0 | K13: =SUM(K8:K12) -> 0 | ... AD13: =SUM(AD8:AD12) -> 0

Sheet 18
A1: ='1'!A1 -> Afaz Tobacco Company .
A2: ='1'!A2 -> Marketing Department
A3: Month:October-2026
A4: ='1'!A4 -> Daily Sales & Closing Stock Information.
B5: Date:18.10.2026 | G5: Division: Ctg South | U5: Wing: Chittagong
A6: SL. NO | B6: Name of Region | C6: Name of Territory | D6: Brand wise Sales (BITCL) | J6: TOTAL SALES | K6: Brand Wise Closing Stock (BITCL) | Q6: TOTAL Stock | R6: Brand wise Sales (BITCL) | W6: Total Zarda Sales Value | X6: Brand Wise Closing Stock (BITCL) | AC6: Total Zarda C.Stock Value | AD6: Express Empty Packet | AE6: Remark
D7: Wilson | E7: Shahara | F7: Express | G7: Nexus | H7: SB | I7: SM | K7: Wilson | L7: Shahara | M7: Express | N7: Nexus | O7: SB | P7: SM | R7: SLB | S7: 22/25 | T7: 99/14 | U7: 33/15 | X7: SLB | Y7: 22/25 | Z7: 99/14 | AA7: 33/15
A8: 1 | B8: Satkania | C8: Kerani hat | D8: 0 | E8: 0 | F8: 0 | G8: 0 | H8: 0 | I8: 0 | J8: =SUM(D8:I8) -> 0 | K8: 0 | L8: 0 | M8: 0 | N8: 0 | O8: 0 | P8: 0 | Q8: =SUM(K8:P8) -> 0 | R8: 0 | S8: 0 | T8: 0 | U8: 0 | V8: 0 | W8: =S8*15+T8*6+U8*8 -> 0 | X8: 0 | Y8: 0 | Z8: 0 | AA8: 0 | AB8: 0 | AC8: =Y8*15+Z8*6+AA8*8 -> 0 | AD8: 0
A9: 2 | C9: Satkania | D9: 0 | E9: 0 | F9: 0 | G9: 0 | H9: 0 | I9: 0 | J9: =SUM(D9:I9) -> 0 | K9: 0 | L9: 0 | M9: 0 | N9: 0 | O9: 0 | P9: 0 | Q9: =SUM(K9:P9) -> 0 | R9: 0 | S9: 0 | T9: 0 | U9: 0 | V9: 0 | W9: =S9*15+T9*6+U9*8 -> 0 | X9: 0 | Y9: 0 | Z9: 0 | AA9: 0 | AB9: 0 | AC9: =Y9*15+Z9*6+AA9*8 -> 0 | AD9: 0
A10: 3 | C10: Bandarban | D10: 0 | E10: 0 | F10: 0 | G10: 0 | H10: 0 | I10: 0 | J10: =SUM(D10:I10) -> 0 | K10: 0 | L10: 0 | M10: 0 | N10: 0 | O10: 0 | P10: 0 | Q10: =SUM(K10:P10) -> 0 | R10: 0 | S10: 0 | T10: 0 | U10: 0 | V10: 0 | W10: =S10*15+T10*6+U10*8 -> 0 | X10: 0 | Y10: 0 | Z10: 0 | AA10: 0 | AB10: 0 | AC10: =Y10*15+Z10*6+AA10*8 -> 0 | AD10: 0
A11: 4 | C11: Rajasthali | D11: 0 | E11: 0 | F11: 0 | G11: 0 | H11: 0 | I11: 0 | J11: =SUM(D11:I11) -> 0 | K11: 0 | L11: 0 | M11: 0 | N11: 0 | O11: 0 | P11: 0 | Q11: =SUM(K11:P11) -> 0 | R11: 0 | S11: 0 | T11: 0 | U11: 0 | V11: 0 | W11: =S11*15+T11*6+U11*8 -> 0 | X11: 0 | Y11: 0 | Z11: 0 | AA11: 0 | AB11: 0 | AC11: =Y11*15+Z11*6+AA11*8 -> 0 | AD11: 0
A12: 5 | C12: Dohazari | D12: 0 | E12: 0 | F12: 0 | G12: 0 | H12: 0 | I12: 0 | J12: =SUM(D12:I12) -> 0 | K12: 0 | L12: 0 | M12: 0 | N12: 0 | O12: 0 | P12: 0 | Q12: =SUM(K12:P12) -> 0 | R12: 0 | S12: 0 | T12: 0 | U12: 0 | V12: 0 | W12: =S12*15+T12*6+U12*8 -> 0 | X12: 0 | Y12: 0 | Z12: 0 | AA12: 0 | AB12: 0 | AC12: =Y12*15+Z12*6+AA12*8 -> 0 | AD12: 0
A13: Satkania Region Total | D13: =SUM(D8:D12) -> 0 | E13: =SUM(E8:E12) -> 0 | F13: =SUM(F8:F12) -> 0 | G13: =SUM(G8:G12) -> 0 | H13: =SUM(H8:H12) -> 0 | I13: =SUM(I8:I12) -> 0 | J13: =SUM(J8:J12) -> 0 | K13: =SUM(K8:K12) -> 0 | ... AD13: =SUM(AD8:AD12) -> 0

Sheet 19
A1: ='1'!A1 -> Afaz Tobacco Company .
A2: ='1'!A2 -> Marketing Department
A3: Month:October-2026
A4: ='1'!A4 -> Daily Sales & Closing Stock Information.
B5: Date:19.10.2026 | G5: Division: Ctg South | U5: Wing: Chittagong
A6: SL. NO | B6: Name of Region | C6: Name of Territory | D6: Brand wise Sales (BITCL) | J6: TOTAL SALES | K6: Brand Wise Closing Stock (BITCL) | Q6: TOTAL Stock | R6: Brand wise Sales (BITCL) | W6: Total Zarda Sales Value | X6: Brand Wise Closing Stock (BITCL) | AC6: Total Zarda C.Stock Value | AD6: Express Empty Packet | AE6: Remark
D7: Wilson | E7: Shahara | F7: Express | G7: Nexus | H7: SB | I7: SM | K7: Wilson | L7: Shahara | M7: Express | N7: Nexus | O7: SB | P7: SM | R7: SLB | S7: 22/25 | T7: 99/14 | U7: 33/15 | X7: SLB | Y7: 22/25 | Z7: 99/14 | AA7: 33/15
A8: 1 | B8: Satkania | C8: Kerani hat | D8: 0 | E8: 0 | F8: 0 | G8: 0 | H8: 0 | I8: 0 | J8: =SUM(D8:I8) -> 0 | K8: 0 | L8: 0 | M8: 0 | N8: 0 | O8: 0 | P8: 0 | Q8: =SUM(K8:P8) -> 0 | R8: 0 | S8: 0 | T8: 0 | U8: 0 | V8: 0 | W8: =S8*15+T8*6+U8*8 -> 0 | X8: 0 | Y8: 0 | Z8: 0 | AA8: 0 | AB8: 0 | AC8: =Y8*15+Z8*6+AA8*8 -> 0 | AD8: 0
A9: 2 | C9: Satkania | D9: 0 | E9: 0 | F9: 0 | G9: 0 | H9: 0 | I9: 0 | J9: =SUM(D9:I9) -> 0 | K9: 0 | L9: 0 | M9: 0 | N9: 0 | O9: 0 | P9: 0 | Q9: =SUM(K9:P9) -> 0 | R9: 0 | S9: 0 | T9: 0 | U9: 0 | V9: 0 | W9: =S9*15+T9*6+U9*8 -> 0 | X9: 0 | Y9: 0 | Z9: 0 | AA9: 0 | AB9: 0 | AC9: =Y9*15+Z9*6+AA9*8 -> 0 | AD9: 0
A10: 3 | C10: Bandarban | D10: 0 | E10: 0 | F10: 0 | G10: 0 | H10: 0 | I10: 0 | J10: =SUM(D10:I10) -> 0 | K10: 0 | L10: 0 | M10: 0 | N10: 0 | O10: 0 | P10: 0 | Q10: =SUM(K10:P10) -> 0 | R10: 0 | S10: 0 | T10: 0 | U10: 0 | V10: 0 | W10: =S10*15+T10*6+U10*8 -> 0 | X10: 0 | Y10: 0 | Z10: 0 | AA10: 0 | AB10: 0 | AC10: =Y10*15+Z10*6+AA10*8 -> 0 | AD10: 0
A11: 4 | C11: Rajasthali | D11: 0 | E11: 0 | F11: 0 | G11: 0 | H11: 0 | I11: 0 | J11: =SUM(D11:I11) -> 0 | K11: 0 | L11: 0 | M11: 0 | N11: 0 | O11: 0 | P11: 0 | Q11: =SUM(K11:P11) -> 0 | R11: 0 | S11: 0 | T11: 0 | U11: 0 | V11: 0 | W11: =S11*15+T11*6+U11*8 -> 0 | X11: 0 | Y11: 0 | Z11: 0 | AA11: 0 | AB11: 0 | AC11: =Y11*15+Z11*6+AA11*8 -> 0 | AD11: 0
A12: 5 | C12: Dohazari | D12: 0 | E12: 0 | F12: 0 | G12: 0 | H12: 0 | I12: 0 | J12: =SUM(D12:I12) -> 0 | K12: 0 | L12: 0 | M12: 0 | N12: 0 | O12: 0 | P12: 0 | Q12: =SUM(K12:P12) -> 0 | R12: 0 | S12: 0 | T12: 0 | U12: 0 | V12: 0 | W12: =S12*15+T12*6+U12*8 -> 0 | X12: 0 | Y12: 0 | Z12: 0 | AA12: 0 | AB12: 0 | AC12: =Y12*15+Z12*6+AA12*8 -> 0 | AD12: 0
A13: Satkania Region Total | D13: =SUM(D8:D12) -> 0 | E13: =SUM(E8:E12) -> 0 | F13: =SUM(F8:F12) -> 0 | G13: =SUM(G8:G12) -> 0 | H13: =SUM(H8:H12) -> 0 | I13: =SUM(I8:I12) -> 0 | J13: =SUM(J8:J12) -> 0 | K13: =SUM(K8:K12) -> 0 | ... AD13: =SUM(AD8:AD12) -> 0

Sheet 20
A1: ='1'!A1 -> Afaz Tobacco Company .
A2: ='1'!A2 -> Marketing Department
A3: Month:October-2026
A4: ='1'!A4 -> Daily Sales & Closing Stock Information.
B5: Date:20.10.2026 | G5: Division: Ctg South | U5: Wing: Chittagong
A6: SL. NO | B6: Name of Region | C6: Name of Territory | D6: Brand wise Sales (BITCL) | J6: TOTAL SALES | K6: Brand Wise Closing Stock (BITCL) | Q6: TOTAL Stock | R6: Brand wise Sales (BITCL) | W6: Total Zarda Sales Value | X6: Brand Wise Closing Stock (BITCL) | AC6: Total Zarda C.Stock Value | AD6: Express Empty Packet | AE6: Remark
D7: Wilson | E7: Shahara | F7: Express | G7: Nexus | H7: SB | I7: SM | K7: Wilson | L7: Shahara | M7: Express | N7: Nexus | O7: SB | P7: SM | R7: SLB | S7: 22/25 | T7: 99/14 | U7: 33/15 | X7: SLB | Y7: 22/25 | Z7: 99/14 | AA7: 33/15
A8: 1 | B8: Satkania | C8: Kerani hat | D8: 0 | E8: 0 | F8: 0 | G8: 0 | H8: 0 | I8: 0 | J8: =SUM(D8:I8) -> 0 | K8: 0 | L8: 0 | M8: 0 | N8: 0 | O8: 0 | P8: 0 | Q8: =SUM(K8:P8) -> 0 | R8: 0 | S8: 0 | T8: 0 | U8: 0 | V8: 0 | W8: =S8*15+T8*6+U8*8 -> 0 | X8: 0 | Y8: 0 | Z8: 0 | AA8: 0 | AB8: 0 | AC8: =Y8*15+Z8*6+AA8*8 -> 0 | AD8: 0
A9: 2 | C9: Satkania | D9: 0 | E9: 0 | F9: 0 | G9: 0 | H9: 0 | I9: 0 | J9: =SUM(D9:I9) -> 0 | K9: 0 | L9: 0 | M9: 0 | N9: 0 | O9: 0 | P9: 0 | Q9: =SUM(K9:P9) -> 0 | R9: 0 | S9: 0 | T9: 0 | U9: 0 | V9: 0 | W9: =S9*15+T9*6+U9*8 -> 0 | X9: 0 | Y9: 0 | Z9: 0 | AA9: 0 | AB9: 0 | AC9: =Y9*15+Z9*6+AA9*8 -> 0 | AD9: 0
A10: 3 | C10: Bandarban | D10: 0 | E10: 0 | F10: 0 | G10: 0 | H10: 0 | I10: 0 | J10: =SUM(D10:I10) -> 0 | K10: 0 | L10: 0 | M10: 0 | N10: 0 | O10: 0 | P10: 0 | Q10: =SUM(K10:P10) -> 0 | R10: 0 | S10: 0 | T10: 0 | U10: 0 | V10: 0 | W10: =S10*15+T10*6+U10*8 -> 0 | X10: 0 | Y10: 0 | Z10: 0 | AA10: 0 | AB10: 0 | AC10: =Y10*15+Z10*6+AA10*8 -> 0 | AD10: 0
A11: 4 | C11: Rajasthali | D11: 0 | E11: 0 | F11: 0 | G11: 0 | H11: 0 | I11: 0 | J11: =SUM(D11:I11) -> 0 | K11: 0 | L11: 0 | M11: 0 | N11: 0 | O11: 0 | P11: 0 | Q11: =SUM(K11:P11) -> 0 | R11: 0 | S11: 0 | T11: 0 | U11: 0 | V11: 0 | W11: =S11*15+T11*6+U11*8 -> 0 | X11: 0 | Y11: 0 | Z11: 0 | AA11: 0 | AB11: 0 | AC11: =Y11*15+Z11*6+AA11*8 -> 0 | AD11: 0
A12: 5 | C12: Dohazari | D12: 0 | E12: 0 | F12: 0 | G12: 0 | H12: 0 | I12: 0 | J12: =SUM(D12:I12) -> 0 | K12: 0 | L12: 0 | M12: 0 | N12: 0 | O12: 0 | P12: 0 | Q12: =SUM(K12:P12) -> 0 | R12: 0 | S12: 0 | T12: 0 | U12: 0 | V12: 0 | W12: =S12*15+T12*6+U12*8 -> 0 | X12: 0 | Y12: 0 | Z12: 0 | AA12: 0 | AB12: 0 | AC12: =Y12*15+Z12*6+AA12*8 -> 0 | AD12: 0
A13: Satkania Region Total | D13: =SUM(D8:D12) -> 0 | E13: =SUM(E8:E12) -> 0 | F13: =SUM(F8:F12) -> 0 | G13: =SUM(G8:G12) -> 0 | H13: =SUM(H8:H12) -> 0 | I13: =SUM(I8:I12) -> 0 | J13: =SUM(J8:J12) -> 0 | K13: =SUM(K8:K12) -> 0 | ... AD13: =SUM(AD8:AD12) -> 0

Sheet 21
A1: ='1'!A1 -> Afaz Tobacco Company .
A2: ='1'!A2 -> Marketing Department
A3: Month:October-2026
A4: ='1'!A4 -> Daily Sales & Closing Stock Information.
B5: Date:21.10.2026 | G5: Division: Ctg South | U5: Wing: Chittagong
A6: SL. NO | B6: Name of Region | C6: Name of Territory | D6: Brand wise Sales (BITCL) | J6: TOTAL SALES | K6: Brand Wise Closing Stock (BITCL) | Q6: TOTAL Stock | R6: Brand wise Sales (BITCL) | W6: Total Zarda Sales Value | X6: Brand Wise Closing Stock (BITCL) | AC6: Total Zarda C.Stock Value | AD6: Express Empty Packet | AE6: Remark
D7: Wilson | E7: Shahara | F7: Express | G7: Nexus | H7: SB | I7: SM | K7: Wilson | L7: Shahara | M7: Express | N7: Nexus | O7: SB | P7: SM | R7: SLB | S7: 22/25 | T7: 99/14 | U7: 33/15 | X7: SLB | Y7: 22/25 | Z7: 99/14 | AA7: 33/15
A8: 1 | B8: Satkania | C8: Kerani hat | D8: 0 | E8: 0 | F8: 0 | G8: 0 | H8: 0 | I8: 0 | J8: =SUM(D8:I8) -> 0 | K8: 0 | L8: 0 | M8: 0 | N8: 0 | O8: 0 | P8: 0 | Q8: =SUM(K8:P8) -> 0 | R8: 0 | S8: 0 | T8: 0 | U8: 0 | V8: 0 | W8: =S8*15+T8*6+U8*8 -> 0 | X8: 0 | Y8: 0 | Z8: 0 | AA8: 0 | AB8: 0 | AC8: =Y8*15+Z8*6+AA8*8 -> 0 | AD8: 0
A9: 2 | C9: Satkania | D9: 0 | E9: 0 | F9: 0 | G9: 0 | H9: 0 | I9: 0 | J9: =SUM(D9:I9) -> 0 | K9: 0 | L9: 0 | M9: 0 | N9: 0 | O9: 0 | P9: 0 | Q9: =SUM(K9:P9) -> 0 | R9: 0 | S9: 0 | T9: 0 | U9: 0 | V9: 0 | W9: =S9*15+T9*6+U9*8 -> 0 | X9: 0 | Y9: 0 | Z9: 0 | AA9: 0 | AB9: 0 | AC9: =Y9*15+Z9*6+AA9*8 -> 0 | AD9: 0
A10: 3 | C10: Bandarban | D10: 0 | E10: 0 | F10: 0 | G10: 0 | H10: 0 | I10: 0 | J10: =SUM(D10:I10) -> 0 | K10: 0 | L10: 0 | M10: 0 | N10: 0 | O10: 0 | P10: 0 | Q10: =SUM(K10:P10) -> 0 | R10: 0 | S10: 0 | T10: 0 | U10: 0 | V10: 0 | W10: =S10*15+T10*6+U10*8 -> 0 | X10: 0 | Y10: 0 | Z10: 0 | AA10: 0 | AB10: 0 | AC10: =Y10*15+Z10*6+AA10*8 -> 0 | AD10: 0
